Workbook
Name ___F: [1]Hoja3!#REF!
Name _1TEXAS_LONG: #REF!
Name _ACC53: #REF!
Name _ACC54: #REF!
Name _ACC56: #REF!
Name _BUT38: #REF!
Name _BUT78: #REF!
Name _EPD15: #REF!
Name _F: [1]Hoja3!#REF!
Name _PAG1: #REF!
Name _TCA704: #REF!
Name _TOR10: #REF!
Name _TOR14: #REF!
Name _TR4: #REF!
Name A: '[3]Encofrado BVR Unispan'!$C$10
Name A_001: [4]puni!$H$51
Name A_002: [4]puni!$H$97
Name A_003: [4]puni!$H$143
Name A_004: [4]puni!$H$189
Name A_005: [4]puni!$H$235
Name A_006: [4]puni!$H$281
Name A_007: [4]puni!$H$327
Name A_008: [4]puni!$H$373
Name A_009: [4]puni!$H$425
Name A_512: [5]puni!$H$143
Name A_IMPRESIÓN_IM: #REF!
Name AA: #REF!
Name abc: #REF!
Name ABRAZ: #REF!
Name ACCESORIOS: #REF!
Name ACER.: #REF!
Name acero: #REF!
Name ACT: #REF!
Name ADEL: #REF!
Name ADELANTO: #REF!
Name ADELANTOAPT: #REF!
Name AE: #REF!
Name AFI: #REF!
Name afirmado: #REF!
Name AFN: #REF!
Name AFNIT: #REF!
Name AFP: #REF!
Name AFPYN: #REF!
Name Agua: #REF!
Name aj_e1: #REF!
Name alambre: #REF!
Name Alizadora: #REF!
Name Almacén_sótano: #REF!
Name AMI: #REF!
Name AN: #REF!
Name ANAC: #REF!
Name Analisis: #REF!
Name AÑO: #REF!
Name apisonadora: #REF!
Name Arancel: #REF!
Name AREA: #REF!
Name Area__cm2: #REF!
Name AREA_COLUMNAS: #REF!
Name Area_mezzanine: #REF!
Name Area_piso1: #REF!

Sheet FLUJO DE CAJA PROYECTADO  (2)
J5: =J12 -> 9 | K5: =K12 -> 10 | L5: =L12 -> 11 | M5: =M12 -> 12 | N5: =N12 -> 13 | O5: =O12 -> 14 | P5: =P12 -> 15 | Q5: =Q12 -> 16 | ... AN5: =AN12 -> 39
I6: Valor total | J6: Valor Unitario | K6: semana 1 | L6: semana 2 | M6: semana 3 | N6: semana 4 | O6: Total Abril 2026 | P6: semana 5 | Q6: semana 6 | R6: semana 7 | S6: semana 8 | T6: Total mayo 2026 | U6: semana 9 | V6: semana 10 | W6: semana 11 | X6: semana 12 | Y6: Total junio 2026 | Z6: semana 13 | AA6: semana 14 | AB6: semana 15 | AC6: semana 16 | AD6: Total julio 2026 | AE6: semana 17 | AF6: semana 18 | AG6: semana 19 | AH6: semana 20 | AI6: Total Agosto 2026 | AJ6: semana 17 | AK6: semana 18 | AL6: semana 19 | AM6: semana 20 | AN6: Total Septiembre 2026
C7: % DE FACTURACIÓN | D7: 530000 | E7: Kg | F7: 4753.95 | G7: =+D7*F7 -> 2519593500 | O7: =SUM(K7:N7) -> 0 | S7: 0 | T7: =SUM(P7:S7) -> 0 | W7: 54616.82 | Y7: =SUM(U7:X7) -> 54616.82 | AA7: 23957.46 | AC7: 25521.41 | AD7: =SUM(Z7:AC7) -> 49478.87 | AF7: 80000 | AH7: 100000 | AI7: =SUM(AE7:AH7) -> 180000 | AK7: 100000 | AM7: 145904.31 | AN7: =SUM(AJ7:AM7) -> 245904.31
I8: =(O7+T7+Y7+AD7+AI7)*J8 -> 1.5690605e+09 | J8: 5523 | M8: 870811200 | O8: =M8 -> 870811200 | T8: =$J$8*T7 -> 0 | U8: =$J$8*U7 -> 0 | V8: =$J$8*V7 -> 0 | W8: =$J$8*W7 -> 3.016487e+08 | X8: =$J$8*X7 -> 0 | Y8: =$J$8*Y7 -> 3.016487e+08 | Z8: =$J$8*Z7 -> 0 | AA8: =$J$8*AA7 -> 1.3231705e+08 | ... AN8: =$J$8*AN7 -> 1.3581295e+09
B12: 1 | C12: 2 | D12: 3 | E12: 4 | F12: 5 | G12: 6 | H12: 7 | I12: 8 | J12: 9 | K12: 10 | L12: 11 | M12: 12 | N12: 13 | O12: 14 | P12: 15 | Q12: 16 | R12: 17 | S12: 18 | T12: 19 | U12: 20 | V12: 21 | W12: 22 | X12: 23 | Y12: 24 | Z12: 25 | AA12: 26 | AB12: 27 | AC12: 28 | AD12: 29 | AE12: 30 | AF12: 31 | AG12: 32 | AH12: 33 | AI12: 34 | AJ12: 35 | AK12: 36 | AL12: 37 | AM12: 38 | AN12: 39
B13: Código | C13: ITEM | D13: Cantidad+desp. | E13: Unidad de medida | F13: Valor Unitario | G13: Total presupuesto | I13: Valor total | J13: Valor Unitario | K13: semana 1 | L13: semana 2 | M13: semana 3 | N13: semana 4 | O13: Total Abril 2026 | P13: semana 5 | Q13: semana 6 | R13: semana 7 | S13: semana 8 | T13: Total mayo 2026 | U13: semana 9 | V13: semana 10 | W13: semana 11 | X13: semana 12 | Y13: Total junio 2026 | Z13: semana 13 | AA13: semana 14 | AB13: semana 15 | AC13: semana 16 | AD13: Total julio 2026 | AE13: semana 17 | AF13: semana 18 | AG13: semana 19 | AH13: semana 20 | AI13: Total Agosto 2026 | AJ13: semana 17 | AK13: semana 18 | AL13: semana 19 | AM13: semana 20 | AN13: Total Septiembre 2026
B14: 1 | C14: Indirectos | G14: =SUM(G15,G22,G26,G29,G39) -> 1.5053398e+08 | I14: =SUM(I15,I22,I26,I29,I39) -> 1.5530062e+08 | J14: =SUM(J15,J22,J26,J29,J39) -> 123876289 | K14: =SUM(K15,K22,K26,K29,K39) -> 0 | L14: =SUM(L15,L22,L26,L29,L39) -> 0 | M14: =SUM(M15,M22,M26,M29,M39) -> 64463869 | N14: =SUM(N15,N22,N26,N29,N39) -> 3097443 | O14: =SUM(O15,O22,O26,O29,O39) -> 67561312 | P14: =SUM(P15,P22,P26,P29,P39) -> 0 | ... AN14: =SUM(AN15,AN22,AN26,AN29,AN39) -> 60108545
B15: 1.1 | C15: Polizas talleres | D15: =SUM(D16:D21) -> 6 | E15: =SUM(E16:E21) -> 0 | F15: =SUM(F16:F21) -> 18295782 | G15: =SUM(G16:G21) -> 18295782 | I15: =SUM(I16:I21) -> 13451751 | J15: =SUM(J16:J21) -> 5917366 | K15: =SUM(K16:K21) -> 0 | L15: =SUM(L16:L21) -> 0 | M15: =SUM(M16:M21) -> 5917366 | N15: =SUM(N16:N21) -> 0 | O15: =SUM(O16:O21) -> 5917366 | P15: =SUM(P16:P21) -> 0 | ... AN15: =SUM(AN16:AN21) -> 7534385
B16: 1.1.1 | C16: Buen manejo de anticipo | D16: 1 | E16: glb | F16: 3512790.2 | G16: =+D16*F16 -> 3512790.2 | I16: =(O16+T16+Y16+AD16+AI16+AN16) -> 1844836.1 | J16: 516713.12 | M16: 516713.12 | O16: =SUM(K16:N16) -> 516713.12 | T16: =SUM(P16:S16) -> 0 | Y16: =SUM(U16:X16) -> 0 | AD16: =SUM(Z16:AC16) -> 0 | AI16: =SUM(AE16:AH16) -> 0 | AM16: 1328123 | AN16: =SUM(AJ16:AM16) -> 1328123
B17: 1.1.2 | C17: Cumplimiento | D17: 1 | E17: glb | F17: 3073691.4 | G17: =+D17*F17 -> 3073691.4 | I17: =(O17+T17+Y17+AD17+AI17+AN17) -> 910373.43 | J17: 465741.43 | M17: 465741.43 | O17: =SUM(K17:N17) -> 465741.43 | T17: =SUM(P17:S17) -> 0 | Y17: =SUM(U17:X17) -> 0 | AD17: =SUM(Z17:AC17) -> 0 | AI17: =SUM(AE17:AH17) -> 0 | AM17: 444632 | AN17: =SUM(AJ17:AM17) -> 444632
B18: 1.1.3 | C18: Salarios y prestaciones sociales | D18: 1 | E18: glb | F18: 2049127.6 | G18: =+D18*F18 -> 2049127.6 | I18: =(O18+T18+Y18+AD18+AI18+AN18) -> 612043.07 | J18: 349306.07 | M18: 349306.07 | O18: =SUM(K18:N18) -> 349306.07 | T18: =SUM(P18:S18) -> 0 | Y18: =SUM(U18:X18) -> 0 | AD18: =SUM(Z18:AC18) -> 0 | AI18: =SUM(AE18:AH18) -> 0 | AM18: 262737 | AN18: =SUM(AJ18:AM18) -> 262737
B19: 1.1.4 | C19: Estabilidad de obra | D19: 1 | E19: glb | F19: 3073691.4 | G19: =+D19*F19 -> 3073691.4 | I19: =(O19+T19+Y19+AD19+AI19+AN19) -> 7879684.9 | J19: 4184037.9 | M19: 4184037.9 | O19: =SUM(K19:N19) -> 4184037.9 | T19: =SUM(P19:S19) -> 0 | Y19: =SUM(U19:X19) -> 0 | AD19: =SUM(Z19:AC19) -> 0 | AI19: =SUM(AE19:AH19) -> 0 | AM19: 3695647 | AN19: =SUM(AJ19:AM19) -> 3695647
B20: 1.1.5 | C20: Calidad de obra | D20: 1 | E20: glb | F20: 3073691.4 | G20: =+D20*F20 -> 3073691.4 | I20: =(O20+T20+Y20+AD20+AI20+AN20) -> 1222251 | J20: 9282 | M20: 9282 | O20: =SUM(K20:N20) -> 9282 | T20: =SUM(P20:S20) -> 0 | Y20: =SUM(U20:X20) -> 0 | AD20: =SUM(Z20:AC20) -> 0 | AI20: =SUM(AE20:AH20) -> 0 | AM20: 1212969 | AN20: =SUM(AJ20:AM20) -> 1212969
B21: 1.1.6 | C21: Responsabilidad civil extracontractural | D21: 1 | E21: glb | F21: 3512790.2 | G21: =+D21*F21 -> 3512790.2 | I21: =(O21+T21+Y21+AD21+AI21+AN21) -> 982562.52 | J21: =197018.52+195267 -> 392285.52 | M21: =197018.52+195267 -> 392285.52 | O21: =SUM(K21:N21) -> 392285.52 | T21: =SUM(P21:S21) -> 0 | Y21: =SUM(U21:X21) -> 0 | AD21: =SUM(Z21:AC21) -> 0 | AI21: =SUM(AE21:AH21) -> 0 | AM21: 590277 | AN21: =SUM(AJ21:AM21) -> 590277
B22: 1.2. | C22: Impuestos | G22: =SUM(G23:G25) -> 48300865 | I22: =SUM(I23:I25) -> 48300865 | J22: =SUM(J23:J25) -> 48300863 | K22: =SUM(K23:K25) -> 0 | L22: =SUM(L23:L25) -> 0 | M22: =SUM(M23:M25) -> 0 | N22: =SUM(N23:N25) -> 0 | O22: =SUM(O23:O25) -> 0 | P22: =SUM(P23:P25) -> 0 | ... AN22: =SUM(AN23:AN25) -> 48300865
B23: 1.2.1 | C23: FIC | D23: 1 | E23: glb | F23: 7318312.9 | G23: =+D23*F23 -> 7318312.9 | I23: =(O23+T23+Y23+AD23+AI23+AN23) -> 7318312.9 | J23: 7318312 | O23: =SUM(K23:N23) -> 0 | T23: =SUM(P23:S23) -> 0 | Y23: =SUM(U23:X23) -> 0 | AD23: =SUM(Z23:AC23) -> 0 | AI23: =SUM(AE23:AH23) -> 0 | AK23: 7318312.9 | AN23: =SUM(AJ23:AM23) -> 7318312.9
B24: 1.2.2 | C24: ICA | D24: 1 | E24: glb | F24: 29273252 | G24: =+D24*F24 -> 29273252 | I24: =(O24+T24+Y24+AD24+AI24+AN24) -> 29273252 | J24: 29273251 | O24: =SUM(K24:N24) -> 0 | T24: =SUM(P24:S24) -> 0 | Y24: =SUM(U24:X24) -> 0 | AD24: =SUM(Z24:AC24) -> 0 | AI24: =SUM(AE24:AH24) -> 0 | AK24: 29273252 | AN24: =SUM(AJ24:AM24) -> 29273252
B25: 1.2.3 | C25: Cuatro por 1000 | D25: 1 | E25: glb | F25: 11709301 | G25: =+D25*F25 -> 11709301 | I25: =(O25+T25+Y25+AD25+AI25+AN25) -> 11709301 | J25: 11709300 | O25: =SUM(K25:N25) -> 0 | T25: =SUM(P25:S25) -> 0 | Y25: =SUM(U25:X25) -> 0 | AD25: =SUM(Z25:AC25) -> 0 | AI25: =SUM(AE25:AH25) -> 0 | AK25: 11709301 | AN25: =SUM(AJ25:AM25) -> 11709301
B26: 1.3 | C26: Personal administración | G26: =G27 -> 24640000 | I26: =SUM(I27:I28) -> 34339945 | J26: =SUM(J27:J28) -> 10450000 | K26: =SUM(K27:K28) -> 0 | L26: =SUM(L27:L28) -> 0 | M26: =SUM(M27:M28) -> 0 | N26: =SUM(N27:N28) -> 2435886 | O26: =SUM(O27:O28) -> 2435886 | P26: =SUM(P27:P28) -> 0 | ... AN26: =SUM(AN27:AN28) -> 4273295
B27: 1.3.1 | C27: Profesional de calidad 100% | D27: 4 | E27: mes | F27: 6160000 | G27: =+D27*F27 -> 24640000 | I27: =(O27+T27+Y27+AD27+AI27+AN27) -> 17089945 | J27: 7000000 | N27: 2435886 | O27: =SUM(K27:N27) -> 2435886 | S27: 6915382 | T27: =SUM(P27:S27) -> 6915382 | X27: 6915382 | Y27: =SUM(U27:X27) -> 6915382 | AD27: =SUM(Z27:AC27) -> 0 | AI27: =SUM(AE27:AH27) -> 0 | AM27: 823295 | AN27: =SUM(AJ27:AM27) -> 823295
B28: 1.3.2 | C28: Residente administrativo | D28: 4 | E28: mes | F28: =2300000*1.5 -> 3450000 | G28: =F28*D28 -> 13800000 | I28: =(O28+T28+Y28+AD28+AI28+AN28) -> 17250000 | J28: =2300000*1.5 -> 3450000 | O28: =SUM(K28:N28) -> 0 | S28: 3450000 | T28: =SUM(P28:S28) -> 3450000 | X28: =2300000*1.5 -> 3450000 | Y28: =SUM(U28:X28) -> 3450000 | AC28: =2300000*1.5 -> 3450000 | AD28: =SUM(Z28:AC28) -> 3450000 | AH28: =2300000*1.5 -> 3450000 | AI28: =SUM(AE28:AH28) -> 3450000 | AM28: =2300000*1.5 -> 3450000 | AN28: =SUM(AJ28:AM28) -> 3450000
B29: 1.4 | C29: Campamentos, protecciones e insumos de obra | G29: =SUM(G30:G38) -> 750834.4 | I29: =SUM(I30:I38) -> 661557 | J29: =SUM(J30:J38) -> 661557 | K29: =SUM(K30:K38) -> 0 | L29: =SUM(L30:L38) -> 0 | M29: =SUM(M30:M38) -> 0 | N29: =SUM(N30:N38) -> 661557 | O29: =SUM(O30:O38) -> 661557 | P29: =SUM(P30:P38) -> 0 | ... AN29: =SUM(AN30:AN38) -> 0
B30: 1.4.1 | C30: Kit señalización para campamentos (hasta 120 m2) | D30: 3 | E30: und | F30: 125384.3 | G30: =+D30*F30 -> 376152.9 | I30: =(O30+T30+Y30+AD30+AI30+AN30) -> 150000 | J30: 150000 | N30: 150000 | O30: =SUM(K30:N30) -> 150000 | T30: =SUM(P30:S30) -> 0 | Y30: =SUM(U30:X30) -> 0 | AD30: =SUM(Z30:AC30) -> 0 | AI30: =SUM(AE30:AH30) -> 0 | AN30: =SUM(AJ30:AM30) -> 0
B31: 1.4.2 | C31: Cascos de seguridad | D31: 1 | E31: und | F31: 17867 | G31: =+D31*F31 -> 17867 | I31: =(O31+T31+Y31+AD31+AI31+AN31) -> 17850 | J31: 17850 | N31: 17850 | O31: =SUM(K31:N31) -> 17850 | T31: =SUM(P31:S31) -> 0 | Y31: =SUM(U31:X31) -> 0 | AD31: =SUM(Z31:AC31) -> 0 | AI31: =SUM(AE31:AH31) -> 0 | AN31: =SUM(AJ31:AM31) -> 0
B32: 1.4.3 | C32: Protección auditiva | D32: 3 | E32: und | F32: 2627.5 | G32: =+D32*F32 -> 7882.5 | I32: =(O32+T32+Y32+AD32+AI32+AN32) -> 4341 | J32: 4341 | N32: 4341 | O32: =SUM(K32:N32) -> 4341 | T32: =SUM(P32:S32) -> 0 | Y32: =SUM(U32:X32) -> 0 | AD32: =SUM(Z32:AC32) -> 0 | AI32: =SUM(AE32:AH32) -> 0 | AN32: =SUM(AJ32:AM32) -> 0
B33: 1.4.4 | C33: Guantes de nitrilo | D33: 3 | E33: und | F33: 5780.5 | G33: =+D33*F33 -> 17341.5 | I33: =(O33+T33+Y33+AD33+AI33+AN33) -> 23324 | J33: 23324 | N33: 23324 | O33: =SUM(K33:N33) -> 23324 | T33: =SUM(P33:S33) -> 0 | Y33: =SUM(U33:X33) -> 0 | AD33: =SUM(Z33:AC33) -> 0 | AI33: =SUM(AE33:AH33) -> 0 | AN33: =SUM(AJ33:AM33) -> 0
B34: 1.4.5 | C34: Par de botas de agua | D34: 1 | E34: und | F34: 72519 | G34: =+D34*F34 -> 72519 | I34: =(O34+T34+Y34+AD34+AI34+AN34) -> 66640 | J34: 66640 | N34: 66640 | O34: =SUM(K34:N34) -> 66640 | T34: =SUM(P34:S34) -> 0 | Y34: =SUM(U34:X34) -> 0 | AD34: =SUM(Z34:AC34) -> 0 | AI34: =SUM(AE34:AH34) -> 0 | AN34: =SUM(AJ34:AM34) -> 0
B35: 1.4.6 | C35: Par de botas de seguridad | D35: 1 | E35: und | F35: 118763 | G35: =+D35*F35 -> 118763 | I35: =(O35+T35+Y35+AD35+AI35+AN35) -> 116739 | J35: 116739 | N35: 116739 | O35: =SUM(K35:N35) -> 116739 | T35: =SUM(P35:S35) -> 0 | Y35: =SUM(U35:X35) -> 0 | AD35: =SUM(Z35:AC35) -> 0 | AI35: =SUM(AE35:AH35) -> 0 | AN35: =SUM(AJ35:AM35) -> 0
B36: 1.4.7 | C36: Gafas de seguridad | D36: 3 | E36: und | F36: 3678.5 | G36: =+D36*F36 -> 11035.5 | I36: =(O36+T36+Y36+AD36+AI36+AN36) -> 14756 | J36: 14756 | N36: 14756 | O36: =SUM(K36:N36) -> 14756 | T36: =SUM(P36:S36) -> 0 | Y36: =SUM(U36:X36) -> 0 | AD36: =SUM(Z36:AC36) -> 0 | AI36: =SUM(AE36:AH36) -> 0 | AN36: =SUM(AJ36:AM36) -> 0
B37: 1.4.8 | C37: Chalecos reflectivos | D37: 1 | E37: und | F37: 78825 | G37: =+D37*F37 -> 78825 | I37: =(O37+T37+Y37+AD37+AI37+AN37) -> 81037 | J37: 81037 | N37: 81037 | O37: =SUM(K37:N37) -> 81037 | T37: =SUM(P37:S37) -> 0 | Y37: =SUM(U37:X37) -> 0 | AD37: =SUM(Z37:AC37) -> 0 | AI37: =SUM(AE37:AH37) -> 0 | AN37: =SUM(AJ37:AM37) -> 0
B38: 1.4.9 | C38: Overoles | D38: 1 | E38: und | F38: 50448 | G38: =+D38*F38 -> 50448 | I38: =(O38+T38+Y38+AD38+AI38+AN38) -> 186870 | J38: 186870 | N38: 186870 | O38: =SUM(K38:N38) -> 186870 | T38: =SUM(P38:S38) -> 0 | Y38: =SUM(U38:X38) -> 0 | AD38: =SUM(Z38:AC38) -> 0 | AI38: =SUM(AE38:AH38) -> 0 | AN38: =SUM(AJ38:AM38) -> 0
B39: 1.5 | C39: G.C. | D39: =SUM(D40) -> 1 | E39: =SUM(E40) -> 0 | F39: =SUM(F40) -> 58546503 | G39: =SUM(G40) -> 58546503 | I39: =SUM(I40) -> 58546503 | J39: =SUM(J40) -> 58546503 | K39: =SUM(K40) -> 0 | L39: =SUM(L40) -> 0 | M39: =SUM(M40) -> 58546503 | N39: =SUM(N40) -> 0 | O39: =SUM(O40) -> 58546503 | P39: =SUM(P40) -> 0 | ... AN39: =SUM(AN40) -> 0
B40: 1.5.1 | C40: TRANSPORTES | D40: 1 | E40: glb | F40: 58546503 | G40: =+D40*F40 -> 58546503 | I40: =(O40+T40+Y40+AD40+AI40+AN40) -> 58546503 | J40: 58546503 | M40: 58546503 | O40: =SUM(K40:N40) -> 58546503 | T40: =SUM(P40:S40) -> 0 | Y40: =SUM(U40:X40) -> 0 | AD40: =SUM(Z40:AC40) -> 0 | AI40: =SUM(AE40:AH40) -> 0 | AN40: =SUM(AJ40:AM40) -> 0
B41: 3 | C41: Viaticos | G41: =G42 -> 0 | I41: =I42 -> 17881010 | J41: =J42 -> 4200000 | K41: =K42 -> 0 | L41: =L42 -> 0 | M41: =M42 -> 0 | N41: =N42 -> 0 | O41: =O42 -> 0 | P41: =P42 -> 1497410 | ... AN41: =AN42 -> 4716200
B42: 3.1 | C42: Viaticos | G42: =SUM(G43:G46) -> 0 | I42: =SUM(I43:I46) -> 17881010 | J42: =SUM(J43:J46) -> 4200000 | K42: =SUM(K43:K46) -> 0 | L42: =SUM(L43:L46) -> 0 | M42: =SUM(M43:M46) -> 0 | N42: =SUM(N43:N46) -> 0 | O42: =SUM(O43:O46) -> 0 | P42: =SUM(P43:P46) -> 1497410 | ... AN42: =SUM(AN43:AN46) -> 4716200
B43: 3.1.1 | C43: Hospedaje | I43: =(O43+T43+Y43+AD43+AI43+AN43) -> 9048000 | J43: 1237600 | O43: =SUM(K43:N43) -> 0 | P43: 500000 | T43: =SUM(P43:S43) -> 500000 | V43: 1348000 | Y43: =SUM(U43:X43) -> 1348000 | AB43: 2400000 | AD43: =SUM(Z43:AC43) -> 2400000 | AG43: 2400000 | AI43: =SUM(AE43:AH43) -> 2400000 | AL43: 2400000 | AN43: =SUM(AJ43:AM43) -> 2400000
B44: 3.1.2 | C44: Transportes | I44: =(O44+T44+Y44+AD44+AI44+AN44) -> 586500 | J44: 292400 | O44: =SUM(K44:N44) -> 0 | P44: 147900 | T44: =SUM(P44:S44) -> 147900 | Y44: =SUM(U44:X44) -> 0 | AB44: 146200 | AD44: =SUM(Z44:AC44) -> 146200 | AG44: 146200 | AI44: =SUM(AE44:AH44) -> 146200 | AL44: 146200 | AN44: =SUM(AJ44:AM44) -> 146200
B45: 3.1.3 | C45: Pasajes | I45: =(O45+T45+Y45+AD45+AI45+AN45) -> 1539510 | J45: 2190000 | O45: =SUM(K45:N45) -> 0 | P45: 609510 | T45: =SUM(P45:S45) -> 609510 | Y45: =SUM(U45:X45) -> 0 | AB45: 310000 | AD45: =SUM(Z45:AC45) -> 310000 | AG45: 310000 | AI45: =SUM(AE45:AH45) -> 310000 | AL45: 310000 | AN45: =SUM(AJ45:AM45) -> 310000
B46: 3.1.4 | C46: Alimentacion | I46: =(O46+T46+Y46+AD46+AI46+AN46) -> 6707000 | J46: 480000 | O46: =SUM(K46:N46) -> 0 | P46: 240000 | T46: =SUM(P46:S46) -> 240000 | V46: 887000 | Y46: =SUM(U46:X46) -> 887000 | AB46: 1860000 | AD46: =SUM(Z46:AC46) -> 1860000 | AG46: 1860000 | AI46: =SUM(AE46:AH46) -> 1860000 | AL46: 1860000 | AN46: =SUM(AJ46:AM46) -> 1860000
B47: 4 | C47: INGENIERÍA | G47: =G48 -> 0 | I47: =I48 -> 11448636 | J47: =J48 -> 11448635 | K47: =K48 -> 0 | L47: =L48 -> 0 | M47: =M48 -> 0 | N47: =N48 -> 0 | O47: =O48 -> 0 | P47: =P48 -> 0 | ... AN47: =AN48 -> 0
...

Sheet FLUJO DE CAJA PROYECTADO  (V1)
B5: 1 | C5: 2 | D5: 3 | E5: 4 | F5: 5 | G5: 6 | H5: 7 | I5: 8 | J5: 9 | K5: 10 | L5: 11 | M5: 12 | N5: 13 | O5: 14 | P5: 15 | Q5: 16 | R5: 17 | S5: 18 | T5: 19 | U5: 20 | V5: 21 | W5: 22 | X5: 23 | Y5: 24 | Z5: 25 | AA5: 26 | AB5: 27 | AC5: 28 | AD5: 29 | AE5: 30 | AF5: 31 | AG5: 32 | AH5: 33 | AI5: 34
B6: Código | C6: ITEM | D6: Cantidad+desp. | E6: Unidad de medida | F6: Valor Unitario | G6: Total presupuesto | I6: Valor total | J6: Valor Unitario | K6: semana 1 | L6: semana 2 | M6: semana 3 | N6: semana 4 | O6: Total Abril 2026 | P6: semana 5 | Q6: semana 6 | R6: semana 7 | S6: semana 8 | T6: Total mayo 2026 | U6: semana 9 | V6: semana 10 | W6: semana 11 | X6: semana 12 | Y6: Total junio 2026 | Z6: semana 13 | AA6: semana 14 | AB6: semana 15 | AC6: semana 16 | AD6: Total julio 2026 | AE6: semana 17 | AF6: semana 18 | AG6: semana 19 | AH6: semana 20 | AI6: Total Agosto 2026
B7: 1 | C7: Indirectos | G7: =SUM(G8,G15,G19,G21,G31) -> 1.5053398e+08 | I7: =SUM(I8,I15,I19,I21,I31) -> 1.5105809e+08 | J7: =SUM(J8,J15,J19,J21,J31) -> 120426289 | K7: =SUM(K8,K15,K19,K21,K31) -> 0 | L7: =SUM(L8,L15,L19,L21,L31) -> 0 | M7: =SUM(M8,M15,M19,M21,M31) -> 64463869 | N7: =SUM(N8,N15,N19,N21,N31) -> 3097443 | O7: =SUM(O8,O15,O19,O21,O31) -> 67561312 | P7: =SUM(P8,P15,P19,P21,P31) -> 0 | ... AI7: =SUM(AI8,AI15,AI19,AI21,AI31) -> 14449767
B8: 1.1 | C8: Polizas talleres | D8: =SUM(D9:D14) -> 6 | E8: =SUM(E9:E14) -> 0 | F8: =SUM(F9:F14) -> 18295782 | G8: =SUM(G9:G14) -> 18295782 | I8: =SUM(I9:I14) -> 13451751 | J8: =SUM(J9:J14) -> 5917366 | K8: =SUM(K9:K14) -> 0 | L8: =SUM(L9:L14) -> 0 | M8: =SUM(M9:M14) -> 5917366 | N8: =SUM(N9:N14) -> 0 | O8: =SUM(O9:O14) -> 5917366 | P8: =SUM(P9:P14) -> 0 | ... AI8: =SUM(AI9:AI14) -> 7534385
B9: 1.1.1 | C9: Buen manejo de anticipo | D9: 1 | E9: glb | F9: 3512790.2 | G9: =+D9*F9 -> 3512790.2 | I9: =O9+T9+Y9+AD9+AI9 -> 1844836.1 | J9: 516713.12 | M9: 516713.12 | O9: =SUM(K9:N9) -> 516713.12 | T9: =SUM(P9:S9) -> 0 | Y9: =SUM(U9:X9) -> 0 | AD9: =SUM(Z9:AC9) -> 0 | AH9: 1328123 | AI9: =SUM(AE9:AH9) -> 1328123
B10: 1.1.2 | C10: Cumplimiento | D10: 1 | E10: glb | F10: 3073691.4 | G10: =+D10*F10 -> 3073691.4 | I10: =O10+T10+Y10+AD10+AI10 -> 910373.43 | J10: 465741.43 | M10: 465741.43 | O10: =SUM(K10:N10) -> 465741.43 | T10: =SUM(P10:S10) -> 0 | Y10: =SUM(U10:X10) -> 0 | AD10: =SUM(Z10:AC10) -> 0 | AH10: 444632 | AI10: =SUM(AE10:AH10) -> 444632
B11: 1.1.3 | C11: Salarios y prestaciones sociales | D11: 1 | E11: glb | F11: 2049127.6 | G11: =+D11*F11 -> 2049127.6 | I11: =O11+T11+Y11+AD11+AI11 -> 612043.07 | J11: 349306.07 | M11: 349306.07 | O11: =SUM(K11:N11) -> 349306.07 | T11: =SUM(P11:S11) -> 0 | Y11: =SUM(U11:X11) -> 0 | AD11: =SUM(Z11:AC11) -> 0 | AH11: 262737 | AI11: =SUM(AE11:AH11) -> 262737
B12: 1.1.4 | C12: Estabilidad de obra | D12: 1 | E12: glb | F12: 3073691.4 | G12: =+D12*F12 -> 3073691.4 | I12: =O12+T12+Y12+AD12+AI12 -> 7879684.9 | J12: 4184037.9 | M12: 4184037.9 | O12: =SUM(K12:N12) -> 4184037.9 | T12: =SUM(P12:S12) -> 0 | Y12: =SUM(U12:X12) -> 0 | AD12: =SUM(Z12:AC12) -> 0 | AH12: 3695647 | AI12: =SUM(AE12:AH12) -> 3695647
B13: 1.1.5 | C13: Calidad de obra | D13: 1 | E13: glb | F13: 3073691.4 | G13: =+D13*F13 -> 3073691.4 | I13: =O13+T13+Y13+AD13+AI13 -> 1222251 | J13: 9282 | M13: 9282 | O13: =SUM(K13:N13) -> 9282 | T13: =SUM(P13:S13) -> 0 | Y13: =SUM(U13:X13) -> 0 | AD13: =SUM(Z13:AC13) -> 0 | AH13: 1212969 | AI13: =SUM(AE13:AH13) -> 1212969
B14: 1.1.6 | C14: Responsabilidad civil extracontractural | D14: 1 | E14: glb | F14: 3512790.2 | G14: =+D14*F14 -> 3512790.2 | I14: =O14+T14+Y14+AD14+AI14 -> 982562.52 | J14: =197018.52+195267 -> 392285.52 | M14: =197018.52+195267 -> 392285.52 | O14: =SUM(K14:N14) -> 392285.52 | T14: =SUM(P14:S14) -> 0 | Y14: =SUM(U14:X14) -> 0 | AD14: =SUM(Z14:AC14) -> 0 | AH14: 590277 | AI14: =SUM(AE14:AH14) -> 590277
B15: 1.2. | C15: Impuestos | G15: =SUM(G16:G18) -> 48300865 | I15: =SUM(I16:I18) -> 48300865 | J15: =SUM(J16:J18) -> 48300863 | K15: =SUM(K16:K18) -> 0 | L15: =SUM(L16:L18) -> 0 | M15: =SUM(M16:M18) -> 0 | N15: =SUM(N16:N18) -> 0 | O15: =SUM(O16:O18) -> 0 | P15: =SUM(P16:P18) -> 0 | ... AI15: =SUM(AI16:AI18) -> 0
B16: 1.2.1 | C16: FIC | D16: 1 | E16: glb | F16: 7318312.9 | G16: =+D16*F16 -> 7318312.9 | I16: =O16+T16+Y16+AD16+AI16 -> 7318312.9 | J16: 7318312 | O16: =SUM(K16:N16) -> 0 | T16: =SUM(P16:S16) -> 0 | Y16: =SUM(U16:X16) -> 0 | AC16: 7318312.9 | AD16: =SUM(Z16:AC16) -> 7318312.9 | AI16: =SUM(AE16:AH16) -> 0
B17: 1.2.2 | C17: ICA | D17: 1 | E17: glb | F17: 29273252 | G17: =+D17*F17 -> 29273252 | I17: =O17+T17+Y17+AD17+AI17 -> 29273252 | J17: 29273251 | O17: =SUM(K17:N17) -> 0 | T17: =SUM(P17:S17) -> 0 | Y17: =SUM(U17:X17) -> 0 | AC17: 29273252 | AD17: =SUM(Z17:AC17) -> 29273252 | AI17: =SUM(AE17:AH17) -> 0
B18: 1.2.3 | C18: Cuatro por 1000 | D18: 1 | E18: glb | F18: 11709301 | G18: =+D18*F18 -> 11709301 | I18: =O18+T18+Y18+AD18+AI18 -> 11709301 | J18: 11709300 | O18: =SUM(K18:N18) -> 0 | T18: =SUM(P18:S18) -> 0 | Y18: =SUM(U18:X18) -> 0 | AC18: 11709301 | AD18: =SUM(Z18:AC18) -> 11709301 | AI18: =SUM(AE18:AH18) -> 0
B19: 1.3 | C19: Personal administración | G19: =G20 -> 24640000 | I19: =I20 -> 30097414 | J19: =J20 -> 7000000 | K19: =K20 -> 0 | L19: =L20 -> 0 | M19: =M20 -> 0 | N19: =N20 -> 2435886 | O19: =O20 -> 2435886 | P19: =P20 -> 0 | ... AI19: =AI20 -> 6915382
B20: 1.3.1 | C20: Profesional de calidad 100% | D20: 4 | E20: mes | F20: 6160000 | G20: =+D20*F20 -> 24640000 | I20: =O20+T20+Y20+AD20+AI20 -> 30097414 | J20: 7000000 | N20: 2435886 | O20: =SUM(K20:N20) -> 2435886 | S20: 6915382 | T20: =SUM(P20:S20) -> 6915382 | X20: 6915382 | Y20: =SUM(U20:X20) -> 6915382 | AC20: 6915382 | AD20: =SUM(Z20:AC20) -> 6915382 | AH20: 6915382 | AI20: =SUM(AE20:AH20) -> 6915382
B21: 1.4 | C21: Campamentos, protecciones e insumos de obra | G21: =SUM(G22:G30) -> 750834.4 | I21: =SUM(I22:I30) -> 661557 | J21: =SUM(J22:J30) -> 661557 | K21: =SUM(K22:K30) -> 0 | L21: =SUM(L22:L30) -> 0 | M21: =SUM(M22:M30) -> 0 | N21: =SUM(N22:N30) -> 661557 | O21: =SUM(O22:O30) -> 661557 | P21: =SUM(P22:P30) -> 0 | ... AI21: =SUM(AI22:AI30) -> 0
B22: 1.4.1 | C22: Kit señalización para campamentos (hasta 120 m2) | D22: 3 | E22: und | F22: 125384.3 | G22: =+D22*F22 -> 376152.9 | I22: =O22+T22+Y22+AD22+AI22 -> 150000 | J22: 150000 | N22: 150000 | O22: =SUM(K22:N22) -> 150000 | T22: =SUM(P22:S22) -> 0 | Y22: =SUM(U22:X22) -> 0 | AD22: =SUM(Z22:AC22) -> 0 | AI22: =SUM(AE22:AH22) -> 0
B23: 1.4.2 | C23: Cascos de seguridad | D23: 1 | E23: und | F23: 17867 | G23: =+D23*F23 -> 17867 | I23: =O23+T23+Y23+AD23+AI23 -> 17850 | J23: 17850 | N23: 17850 | O23: =SUM(K23:N23) -> 17850 | T23: =SUM(P23:S23) -> 0 | Y23: =SUM(U23:X23) -> 0 | AD23: =SUM(Z23:AC23) -> 0 | AI23: =SUM(AE23:AH23) -> 0
B24: 1.4.3 | C24: Protección auditiva | D24: 3 | E24: und | F24: 2627.5 | G24: =+D24*F24 -> 7882.5 | I24: =O24+T24+Y24+AD24+AI24 -> 4341 | J24: 4341 | N24: 4341 | O24: =SUM(K24:N24) -> 4341 | T24: =SUM(P24:S24) -> 0 | Y24: =SUM(U24:X24) -> 0 | AD24: =SUM(Z24:AC24) -> 0 | AI24: =SUM(AE24:AH24) -> 0
B25: 1.4.4 | C25: Guantes de nitrilo | D25: 3 | E25: und | F25: 5780.5 | G25: =+D25*F25 -> 17341.5 | I25: =O25+T25+Y25+AD25+AI25 -> 23324 | J25: 23324 | N25: 23324 | O25: =SUM(K25:N25) -> 23324 | T25: =SUM(P25:S25) -> 0 | Y25: =SUM(U25:X25) -> 0 | AD25: =SUM(Z25:AC25) -> 0 | AI25: =SUM(AE25:AH25) -> 0
B26: 1.4.5 | C26: Par de botas de agua | D26: 1 | E26: und | F26: 72519 | G26: =+D26*F26 -> 72519 | I26: =O26+T26+Y26+AD26+AI26 -> 66640 | J26: 66640 | N26: 66640 | O26: =SUM(K26:N26) -> 66640 | T26: =SUM(P26:S26) -> 0 | Y26: =SUM(U26:X26) -> 0 | AD26: =SUM(Z26:AC26) -> 0 | AI26: =SUM(AE26:AH26) -> 0
B27: 1.4.6 | C27: Par de botas de seguridad | D27: 1 | E27: und | F27: 118763 | G27: =+D27*F27 -> 118763 | I27: =O27+T27+Y27+AD27+AI27 -> 116739 | J27: 116739 | N27: 116739 | O27: =SUM(K27:N27) -> 116739 | T27: =SUM(P27:S27) -> 0 | Y27: =SUM(U27:X27) -> 0 | AD27: =SUM(Z27:AC27) -> 0 | AI27: =SUM(AE27:AH27) -> 0
B28: 1.4.7 | C28: Gafas de seguridad | D28: 3 | E28: und | F28: 3678.5 | G28: =+D28*F28 -> 11035.5 | I28: =O28+T28+Y28+AD28+AI28 -> 14756 | J28: 14756 | N28: 14756 | O28: =SUM(K28:N28) -> 14756 | T28: =SUM(P28:S28) -> 0 | Y28: =SUM(U28:X28) -> 0 | AD28: =SUM(Z28:AC28) -> 0 | AI28: =SUM(AE28:AH28) -> 0
B29: 1.4.8 | C29: Chalecos reflectivos | D29: 1 | E29: und | F29: 78825 | G29: =+D29*F29 -> 78825 | I29: =O29+T29+Y29+AD29+AI29 -> 81037 | J29: 81037 | N29: 81037 | O29: =SUM(K29:N29) -> 81037 | T29: =SUM(P29:S29) -> 0 | Y29: =SUM(U29:X29) -> 0 | AD29: =SUM(Z29:AC29) -> 0 | AI29: =SUM(AE29:AH29) -> 0
B30: 1.4.9 | C30: Overoles | D30: 1 | E30: und | F30: 50448 | G30: =+D30*F30 -> 50448 | I30: =O30+T30+Y30+AD30+AI30 -> 186870 | J30: 186870 | N30: 186870 | O30: =SUM(K30:N30) -> 186870 | T30: =SUM(P30:S30) -> 0 | Y30: =SUM(U30:X30) -> 0 | AD30: =SUM(Z30:AC30) -> 0 | AI30: =SUM(AE30:AH30) -> 0
B31: 1.5 | C31: G.C. | D31: =SUM(D32) -> 1 | E31: =SUM(E32) -> 0 | F31: =SUM(F32) -> 58546503 | G31: =SUM(G32) -> 58546503 | I31: =SUM(I32) -> 58546503 | J31: =SUM(J32) -> 58546503 | K31: =SUM(K32) -> 0 | L31: =SUM(L32) -> 0 | M31: =SUM(M32) -> 58546503 | N31: =SUM(N32) -> 0 | O31: =SUM(O32) -> 58546503 | P31: =SUM(P32) -> 0 | ... AI31: =SUM(AI32) -> 0
B32: 1.5.1 | C32: TRANSPORTES | D32: 1 | E32: glb | F32: 58546503 | G32: =+D32*F32 -> 58546503 | I32: =O32+T32+Y32+AD32+AI32 -> 58546503 | J32: 58546503 | M32: 58546503 | O32: =SUM(K32:N32) -> 58546503 | T32: =SUM(P32:S32) -> 0 | Y32: =SUM(U32:X32) -> 0 | AD32: =SUM(Z32:AC32) -> 0 | AI32: =SUM(AE32:AH32) -> 0
B33: 3 | C33: Viaticos | G33: =G34 -> 0 | I33: =I34 -> 4200000 | J33: =J34 -> 4200000 | K33: =K34 -> 0 | L33: =L34 -> 0 | M33: =M34 -> 0 | N33: =N34 -> 0 | O33: =O34 -> 0 | P33: =P34 -> 1850000 | ... AI33: =AI34 -> 0
B34: 3.1 | C34: Viaticos | G34: =SUM(G35:G38) -> 0 | I34: =SUM(I35:I38) -> 4200000 | J34: =SUM(J35:J38) -> 4200000 | K34: =SUM(K35:K38) -> 0 | L34: =SUM(L35:L38) -> 0 | M34: =SUM(M35:M38) -> 0 | N34: =SUM(N35:N38) -> 0 | O34: =SUM(O35:O38) -> 0 | P34: =SUM(P35:P38) -> 1850000 | ... AI34: =SUM(AI35:AI38) -> 0
B35: 3.1.1 | C35: Hospedaje | I35: =O35+T35+Y35+AD35+AI35 -> 1237600 | J35: 1237600 | O35: =SUM(K35:N35) -> 0 | P35: 618800 | T35: =SUM(P35:S35) -> 618800 | Y35: =SUM(U35:X35) -> 0 | AB35: 618800 | AD35: =SUM(Z35:AC35) -> 618800 | AI35: =SUM(AE35:AH35) -> 0
B36: 3.1.2 | C36: Transportes | I36: =O36+T36+Y36+AD36+AI36 -> 292400 | J36: 292400 | O36: =SUM(K36:N36) -> 0 | P36: 146200 | T36: =SUM(P36:S36) -> 146200 | Y36: =SUM(U36:X36) -> 0 | AB36: 146200 | AD36: =SUM(Z36:AC36) -> 146200 | AI36: =SUM(AE36:AH36) -> 0
B37: 3.1.3 | C37: Pasajes | I37: =O37+T37+Y37+AD37+AI37 -> 2190000 | J37: 2190000 | O37: =SUM(K37:N37) -> 0 | P37: 845000 | T37: =SUM(P37:S37) -> 845000 | V37: 500000 | Y37: =SUM(U37:X37) -> 500000 | AB37: 845000 | AD37: =SUM(Z37:AC37) -> 845000 | AI37: =SUM(AE37:AH37) -> 0
B38: 3.1.4 | C38: Alimentacion | I38: =O38+T38+Y38+AD38+AI38 -> 480000 | J38: 480000 | O38: =SUM(K38:N38) -> 0 | P38: 240000 | T38: =SUM(P38:S38) -> 240000 | Y38: =SUM(U38:X38) -> 0 | AB38: 240000 | AD38: =SUM(Z38:AC38) -> 240000 | AI38: =SUM(AE38:AH38) -> 0
B39: 4 | C39: INGENIERÍA | G39: =G40 -> 0 | I39: =I40 -> 11448636 | J39: =J40 -> 11448635 | K39: =K40 -> 0 | L39: =L40 -> 0 | M39: =M40 -> 0 | N39: =N40 -> 0 | O39: =O40 -> 0 | P39: =P40 -> 0 | ... AI39: =AI40 -> 0
B40: 4.1 | C40: Ingenieria de taller | G40: =G41 -> 0 | I40: =I41 -> 11448636 | J40: =J41 -> 11448635 | K40: =K41 -> 0 | L40: =L41 -> 0 | M40: =M41 -> 0 | N40: =N41 -> 0 | O40: =O41 -> 0 | P40: =P41 -> 0 | ... AI40: =AI41 -> 0
B41: 4.1.1 | C41: Ingenieria de taller | I41: =O41+T41+Y41+AD41+AI41 -> 11448636 | J41: 11448635 | O41: =SUM(K41:N41) -> 0 | Q41: 5724317.5 | S41: 5724318 | T41: =SUM(P41:S41) -> 11448636 | Y41: =SUM(U41:X41) -> 0 | AD41: =SUM(Z41:AC41) -> 0 | AI41: =SUM(AE41:AH41) -> 0
B42: 5 | C42: Suministros | G42: =SUM(G43) -> 0 | I42: =SUM(I43) -> 2.4344444e+08 | J42: =SUM(J43) -> 2045743.3 | K42: =SUM(K43) -> 0 | L42: =SUM(L43) -> 0 | M42: =SUM(M43) -> 0 | N42: =SUM(N43) -> 0 | O42: =SUM(O43) -> 0 | P42: =SUM(P43) -> 0 | ... AI42: =SUM(AI43) -> 0
B43: 5.1 | C43: PINTURA | G43: =G45 -> 0 | I43: =I44+I48 -> 2.4344444e+08 | J43: =J44+J48 -> 2045743.3 | K43: =K44+K48 -> 0 | L43: =L44+L48 -> 0 | M43: =M44+M48 -> 0 | N43: =N44+N48 -> 0 | O43: =O44+O48 -> 0 | P43: =P44+P48 -> 0 | ... AI43: =AI44+AI48 -> 0
B44: 5.1.1 | C44: Epoxico | I44: =SUM(I45:I47) -> 93907565 | J44: =SUM(J45:J47) -> 866096.28 | K44: =SUM(K45:K47) -> 0 | L44: =SUM(L45:L47) -> 0 | M44: =SUM(M45:M47) -> 0 | N44: =SUM(N45:N47) -> 0 | O44: =SUM(O45:O47) -> 0 | P44: =SUM(P45:P47) -> 0 | ... AI44: =SUM(AI45:AI47) -> 0
...

Sheet Resumen
B2: Cuadro de Control
B4: =+C6 -> NORTON EDIFICIOS INDUSTRIALES COLOMBIA SAS
B6: EMPRESA: | C6: NORTON EDIFICIOS INDUSTRIALES COLOMBIA SAS
B7: DOMICILIO: | C7: Calle 93 # 12 - 14, Edificio Tempo 93, Oficina 704
B9: OBRA: | C9: 16-16 | F9: CÓDIGO:
B10: UBICACIÓN: | C10: Bogota | F10: FECHA: | G10: =TODAY() -> 46275
B14: Resumen consolidado | F14: 2927325150
B15: GRUPO | C15: TOTAL | D15: Porcentaje | F15: COSTO | G15: MARGEN
B16: Presupuesto | C16: ='FLUJO DE CAJA PRESU'!D18+'FLUJO DE CAJA PRESU'!D30 -> 2670127485 | D16: 1 | F16: =C16/$F$14 -> 0.91213902 | G16: =1-F16 -> 0.087860983
B17: Proyectado | C17: ='FLUJO DE CAJA PROYECTADO '!I66 -> 2.791884e+09 | D17: =C17/C16 -> 1.0455995 | F17: =C17/$F$14 -> 0.95373212 | G17: =1-F17 -> 0.04626788
B18: Avance de Obra | D18: ='CURVA S'!L21 -> 0.42502835 | F18: =SUM('CURVA S'!I4:I37) -> 2.4714021
B20: Ingresos Real | C20: ='Control Flujo de caja'!V88 -> 1.1021602e+09 | D20: =C20/F14 -> 0.3765076 | F20: =C20/$F$14 -> 0.3765076
B21: Egresos real | C21: ='Control Flujo de caja'!V90 -> 1.1496763e+09 | D21: =C21/C17 -> 0.41179227 | F21: =C21/$F$14 -> 0.39273951 | G21: =1-F21 -> 0.60726049
B22: Avance Contabilidad | C22: =Contabilidad!D53 -> 62862623 | D22: =C22/C17 -> 0.022516202 | F22: =C22/$F$14 -> 0.021474425 | G22: =1-F22 -> 0.97852558
B24: Costo de punto de margen | C24: =F14*0.01 -> 29273252
B25: Margen acumulado a hoy | C25: =C20-C21 -> -47516098
C28: =F14-C17 -> 1.3544113e+08

Sheet Control Flujo de caja
B7: =+C9 -> NORTON EDIFICIOS INDUSTRIALES COLOMBIA SAS
B9: EMPRESA: | C9: NORTON EDIFICIOS INDUSTRIALES COLOMBIA SAS
B10: DOMICILIO: | C10: Calle 93 # 12 - 14, Edificio Tempo 93, Oficina 704
B12: OBRA: | C12: 16-16 | E12: CÓDIGO:
B13: UBICACIÓN: | C13: Bogota | E13: FECHA:
X16: ='FLUJO DE CAJA PROYECTADO '!O12 -> 14 | Y16: =REAL!O12 -> 14 | AA16: ='FLUJO DE CAJA PROYECTADO '!T12 -> 19 | AB16: =AA16 -> 19 | AC16: 2 | AD16: ='FLUJO DE CAJA PROYECTADO '!Y12 -> 24 | AE16: =AD16 -> 24 | AG16: =AD16+5 -> 29 | AH16: =AG16 -> 29 | AJ16: =AG16+5 -> 34 | AK16: =AJ16 -> 34 | AM16: =AJ16+5 -> 39 | AN16: =AM16 -> 39 | AP16: 44 | AQ16: 44
C17: DATOS DE EXPLOTACIÓN | D17: Meses o costo/u | E17: Detalles | X17: ABRIL | AA17: MAYO | AD17: JUNIO | AG17: JULIO | AJ17: AGOSTO | AM17: SEPTIEMBRE | AP17: OCTUBRE
X18: Proyectado | Y18: ="Real"&Z17 -> Real | Z18: Diferencia | AA18: Proyectado | AB18: ="Real"&AC17 -> Real | AC18: Diferencia | AD18: Proyectado | AE18: ="Real"&AF17 -> Real | AF18: Diferencia | AG18: Proyectado | AH18: ="Real"&AI17 -> Real | AI18: Diferencia | AJ18: Proyectado | AK18: ="Real"&AL17 -> Real | AL18: Diferencia | AM18: Proyectado | AN18: ="Real"&AO17 -> Real | AO18: Diferencia | AP18: Proyectado | AQ18: ="Real"&AR17 -> Real | AR18: Diferencia
AE19: =AE76 -> 1.5515135e+08
C20: % DE FACTURACIÓN | W20: % DE FACTURACIÓN
C21: FACTURACION PROYECTO | D21: 2927325150 | W21: FACTURACION PROYECTO | AA21: =HLOOKUP(AA16,'FLUJO DE CAJA PROYECTADO '!$I$5:$AN$8,4,FALSE) -> 0 | AB21: =HLOOKUP(AB16,REAL!$H$5:$AN$8,4,FALSE) -> 0 | AD21: =HLOOKUP(AD16,'FLUJO DE CAJA PROYECTADO '!$I$5:$AN$8,4,FALSE) -> 3.016487e+08 | AE21: =HLOOKUP(AE16,REAL!$H$5:$AN$8,4,FALSE) -> 3.016487e+08 | AG21: =HLOOKUP(AG16,'FLUJO DE CAJA PROYECTADO '!$I$5:$AN$8,4,FALSE) -> 2.732718e+08 | AH21: =HLOOKUP(AH16,REAL!$H$5:$AN$8,4,FALSE) -> 3.0440545e+08 | AJ21: =HLOOKUP(AJ16,'FLUJO DE CAJA PROYECTADO '!$I$5:$AN$8,4,FALSE) -> 994140000 | AK21: =HLOOKUP(AK16,REAL!$H$5:$AN$8,4,FALSE) -> 3.2349017e+08 | AM21: =HLOOKUP(AM16,'FLUJO DE CAJA PROYECTADO '!$I$5:$AN$8,4,FALSE) -> 552300000 | AN21: =HLOOKUP(AN16,REAL!$H$5:$AN$8,4,FALSE) -> 172615842 | AP21: =HLOOKUP(AP16,'FLUJO DE CAJA PROYECTADO '!$I$5:$AZ$8,4,FALSE) -> 805833315 | AQ21: =HLOOKUP(AQ16,REAL!$H$5:$AZ$8,4,FALSE) -> 0
C22: VALOR FACTURADO | W22: VALOR FACTURADO
C23: ANTICIPO | W23: ANTICIPO | X23: 870811200 | Y23: 870811200
W24: Total | X24: =X21+X23 -> 870811200 | Y24: =Y21+Y23 -> 870811200 | Z24: =Z21+Z23 -> 0 | AA24: =AA21+AA23 -> 0 | AB24: =AB21+AB23 -> 0 | AC24: =AC21+AC23 -> 0 | AD24: =AD21+AD23 -> 3.016487e+08 | AE24: =AE21+AE23 -> 3.016487e+08 | ... AR24: =AR21+AR23 -> 0
D26: Presupuesto | E26: Proyectado | J26: Asegurado | P26: Real | U26: Contabilidad | X26: ABRIL | AA26: MAYO | AD26: JUNIO | AG26: JULIO | AJ26: AGOSTO | AM26: SEPTIEMBRE | AP26: octubre
B27: Código | C27: ITEM | D27: Valor Unitario | E27: Cantidad | F27: Valor Unitario | G27: Total proyectado | H27: Desviacion | J27: Cantidad | K27: Valor Unitario | L27: Total proyectado | M27: Desviacion | P27: Cantidad | Q27: Valor Unitario | R27: Total proyectado | S27: Desviacion | U27: Proyectado | V27: Desviacion | X27: Proyectado | Y27: ="Real"&Z26 -> Real | Z27: Desviacion | AA27: Proyectado | AB27: ="Real"&AC26 -> Real | AC27: Desviacion | AD27: Proyectado | AE27: ="Real"&AF26 -> Real | AF27: Desviacion | AG27: Proyectado | AH27: ="Real"&AI26 -> Real | AI27: Desviacion | AJ27: Proyectado | AK27: ="Real"&AL26 -> Real | AL27: Desviacion | AM27: Proyectado | AN27: ="Real"&AO26 -> Real | AO27: Desviacion | AP27: Proyectado | AQ27: ="Real"&AR26 -> Real | AR27: Desviacion
B28: 1 | C28: Indirectos | D28: =SUM(D29,D36,D40,D43,D53) -> 150533984 | E28: =SUM(E29,E36,E40,E43,E53) -> 31 | F28: =SUM(F29,F36,F40,F43,F53) -> 120426289 | G28: =SUM(G29,G36,G40,G43,G53) -> 99465371 | H28: =D28-G28 -> 51068613 | J28: =SUM(J29,J36,J40,J43,J53) -> 31 | K28: =SUM(K29,K36,K40,K43,K53) -> 120426289 | L28: =SUM(L29,L36,L40,L43,L53) -> 66899755 | M28: =SUM(M29,M36,M40,M43,M53) -> 15315616 | P28: =SUM(P29,P36,P40,P43,P53) -> 35 | Q28: =SUM(Q29,Q36,Q40,Q43,Q53) -> 123876289 | R28: =SUM(R29,R36,R40,R43,R53) -> 88200771 | S28: =G28-R28 -> 11264600 | U28: =SUM(#REF!,U29,U37,U43,#REF!,#REF!,#REF!,#REF!,#REF!,U46) -> #REF! | V28: =SUM(V29,V36,V40,V43,V53) -> 62987523 | X28: =SUM(X29,X36,X40,X43,X53) -> 67561312 | Y28: =SUM(Y29,Y36,Y40,Y43,Y53) -> 66899755 | Z28: =SUM(Z29,Z36,Z40,Z43,Z53) -> 661557 | AA28: =SUM(AA29,AA36,AA40,AA43,AA53) -> 10365382 | AB28: =SUM(AB29,AB36,AB40,AB43,AB53) -> 10362570 | AC28: =SUM(AC29,AC36,AC40,AC43,AC53) -> 2812 | AD28: =SUM(AD29,AD36,AD40,AD43,AD53) -> 10365382 | AE28: =SUM(AE29,AE36,AE40,AE43,AE53) -> 7315258 | ... AR28: =SUM(AR29,AR36,AR40,AR43,AR53) -> 60108545
B29: 1.1 | C29: Polizas talleres | D29: 18295782 | E29: =SUM(E30:E35) -> 6 | F29: =SUM(F30:F35) -> 5917366 | G29: =SUM(G30:G35) -> 5917366 | H29: =D29-G29 -> 12378416 | J29: =SUM(J30:J35) -> 6 | K29: =SUM(K30:K35) -> 5917366 | L29: =SUM(L30:L35) -> 5917366 | M29: =SUM(M30:M35) -> 0 | P29: =SUM(P30:P35) -> 6 | Q29: =SUM(Q30:Q35) -> 5917366 | R29: =SUM(R30:R35) -> 5917366 | S29: =G29-R29 -> 0 | U29: =VLOOKUP(B29,Contabilidad!$B$3:$D$51,3,FALSE) -> 5917366.9 | V29: =SUM(V30:V35) -> -0.86 | X29: =SUM(X30:X35) -> 5917366 | Y29: =SUM(Y30:Y35) -> 5917366 | Z29: =SUM(Z30:Z35) -> 0 | AA29: =SUM(AA30:AA35) -> 0 | AB29: =SUM(AB30:AB35) -> 0 | AC29: =SUM(AC30:AC35) -> 0 | AD29: =SUM(AD30:AD35) -> 0 | AE29: =SUM(AE30:AE35) -> 0 | ... AR29: =SUM(AR30:AR35) -> 7534385
B30: 1.1.1 | C30: Buen manejo de anticipo | E30: =VLOOKUP(B30,'FLUJO DE CAJA PROYECTADO '!$B$13:$J$61,3,FALSE) -> 1 | F30: =VLOOKUP(B30,'FLUJO DE CAJA PROYECTADO '!$B$13:$J$61,9,FALSE) -> 516713.12 | G30: =VLOOKUP(B30,'FLUJO DE CAJA PROYECTADO '!$B$13:$J$61,8,FALSE) -> 516713.12 | H30: =D30-G30 -> -516713.12 | J30: =VLOOKUP($B30,ASEGURADO!$B$3:$J$51,3,FALSE) -> 1 | K30: =VLOOKUP(B30,ASEGURADO!$B$3:$J$52,9,FALSE) -> 516713.12 | L30: =VLOOKUP($B30,ASEGURADO!$B$3:$J$52,8,FALSE) -> 516713.12 | M30: =G30-L30 -> 0 | P30: =VLOOKUP(B30,REAL!$B$13:$J$61,3,FALSE) -> 1 | Q30: =VLOOKUP(B30,REAL!$B$13:$J$61,9,FALSE) -> 516713.12 | R30: =VLOOKUP(B30,REAL!$B$13:$J$61,8,FALSE) -> 516713.12 | S30: =G30-R30 -> 0 | U30: =VLOOKUP(B30,Contabilidad!$B$3:$D$51,3,FALSE) -> 0 | V30: =R30-U30 -> 516713.12 | X30: =VLOOKUP($B30,'FLUJO DE CAJA PROYECTADO '!$B$13:$AI$66,'Control Flujo de caja'!X$16,FALSE) -> 516713.12 | Y30: =VLOOKUP($B30,REAL!$B$13:$AI$61,'Control Flujo de caja'!Y$16,FALSE) -> 516713.12 | Z30: =X30-Y30 -> 0 | AA30: =VLOOKUP($B30,'FLUJO DE CAJA PROYECTADO '!$B$13:$AI$66,'Control Flujo de caja'!AA$16,FALSE) -> 0 | AB30: =VLOOKUP($B30,REAL!$B$13:$AI$61,'Control Flujo de caja'!AB$16,FALSE) -> 0 | AC30: =AA30-AB30 -> 0 | AD30: =VLOOKUP($B30,'FLUJO DE CAJA PROYECTADO '!$B$13:$AI$66,'Control Flujo de caja'!AD$16,FALSE) -> 0 | AE30: =VLOOKUP($B30,REAL!$B$13:$AI$61,'Control Flujo de caja'!AE$16,FALSE) -> 0 | AF30: =AD30-AE30 -> 0 | AG30: =VLOOKUP($B30,'FLUJO DE CAJA PROYECTADO '!$B$13:$AI$66,'Control Flujo de caja'!AG$16,FALSE) -> 0 | AH30: =VLOOKUP($B30,REAL!$B$13:$AI$61,'Control Flujo de caja'!AH$16,FALSE) -> 0 | AI30: =AG30-AH30 -> 0 | AJ30: =VLOOKUP($B30,'FLUJO DE CAJA PROYECTADO '!$B$13:$AI$66,'Control Flujo de caja'!AJ$16,FALSE) -> 0 | AK30: =VLOOKUP($B30,REAL!$B$13:$AI$61,'Control Flujo de caja'!AK$16,FALSE) -> 0 | AL30: =AJ30-AK30 -> 0 | AM30: =VLOOKUP($B30,'FLUJO DE CAJA PROYECTADO '!$B$13:$AN$66,'Control Flujo de caja'!AM$16,FALSE) -> 0 | AN30: =VLOOKUP($B30,REAL!$B$13:$AN$61,'Control Flujo de caja'!AN$16,FALSE) -> 0 | AO30: =AM30-AN30 -> 0 | AP30: =VLOOKUP($B30,'FLUJO DE CAJA PROYECTADO '!$B$13:$AS$66,'Control Flujo de caja'!AP$16,FALSE) -> 1328123 | AQ30: =VLOOKUP($B30,REAL!$B$13:$AS$61,'Control Flujo de caja'!AQ$16,FALSE) -> 0 | AR30: =AP30-AQ30 -> 1328123
B31: 1.1.2 | C31: Cumplimiento | E31: =VLOOKUP(B31,'FLUJO DE CAJA PROYECTADO '!$B$13:$J$61,3,FALSE) -> 1 | F31: =VLOOKUP(B31,'FLUJO DE CAJA PROYECTADO '!$B$13:$J$61,9,FALSE) -> 465741.43 | G31: =VLOOKUP(B31,'FLUJO DE CAJA PROYECTADO '!$B$13:$J$61,8,FALSE) -> 465741.43 | H31: =D31-G31 -> -465741.43 | J31: =VLOOKUP($B31,ASEGURADO!$B$3:$J$51,3,FALSE) -> 1 | K31: =VLOOKUP(B31,ASEGURADO!$B$3:$J$52,9,FALSE) -> 465741.43 | L31: =VLOOKUP($B31,ASEGURADO!$B$3:$J$52,8,FALSE) -> 465741.43 | M31: =G31-L31 -> 0 | P31: =VLOOKUP(B31,REAL!$B$13:$J$61,3,FALSE) -> 1 | Q31: =VLOOKUP(B31,REAL!$B$13:$J$61,9,FALSE) -> 465741.43 | R31: =VLOOKUP(B31,REAL!$B$13:$J$61,8,FALSE) -> 465741.43 | S31: =G31-R31 -> 0 | U31: =VLOOKUP(B31,Contabilidad!$B$3:$D$51,3,FALSE) -> 5917366.9 | V31: =R31-U31 -> -5451625.4 | X31: =VLOOKUP($B31,'FLUJO DE CAJA PROYECTADO '!$B$13:$AI$66,'Control Flujo de caja'!X$16,FALSE) -> 465741.43 | Y31: =VLOOKUP($B31,REAL!$B$13:$AI$61,'Control Flujo de caja'!Y$16,FALSE) -> 465741.43 | Z31: =X31-Y31 -> 0 | AA31: =VLOOKUP($B31,'FLUJO DE CAJA PROYECTADO '!$B$13:$AI$66,'Control Flujo de caja'!AA$16,FALSE) -> 0 | AB31: =VLOOKUP($B31,REAL!$B$13:$AI$61,'Control Flujo de caja'!AB$16,FALSE) -> 0 | AC31: =AA31-AB31 -> 0 | AD31: =VLOOKUP($B31,'FLUJO DE CAJA PROYECTADO '!$B$13:$AI$66,'Control Flujo de caja'!AD$16,FALSE) -> 0 | AE31: =VLOOKUP($B31,REAL!$B$13:$AI$61,'Control Flujo de caja'!AE$16,FALSE) -> 0 | AF31: =AD31-AE31 -> 0 | AG31: =VLOOKUP($B31,'FLUJO DE CAJA PROYECTADO '!$B$13:$AI$66,'Control Flujo de caja'!AG$16,FALSE) -> 0 | AH31: =VLOOKUP($B31,REAL!$B$13:$AI$61,'Control Flujo de caja'!AH$16,FALSE) -> 0 | AI31: =AG31-AH31 -> 0 | AJ31: =VLOOKUP($B31,'FLUJO DE CAJA PROYECTADO '!$B$13:$AI$66,'Control Flujo de caja'!AJ$16,FALSE) -> 0 | AK31: =VLOOKUP($B31,REAL!$B$13:$AI$61,'Control Flujo de caja'!AK$16,FALSE) -> 0 | AL31: =AJ31-AK31 -> 0 | AM31: =VLOOKUP($B31,'FLUJO DE CAJA PROYECTADO '!$B$13:$AN$66,'Control Flujo de caja'!AM$16,FALSE) -> 0 | AN31: =VLOOKUP($B31,REAL!$B$13:$AN$61,'Control Flujo de caja'!AN$16,FALSE) -> 0 | AO31: =AM31-AN31 -> 0 | AP31: =VLOOKUP($B31,'FLUJO DE CAJA PROYECTADO '!$B$13:$AS$66,'Control Flujo de caja'!AP$16,FALSE) -> 444632 | AQ31: =VLOOKUP($B31,REAL!$B$13:$AS$61,'Control Flujo de caja'!AQ$16,FALSE) -> 0 | AR31: =AP31-AQ31 -> 444632
B32: 1.1.3 | C32: Salarios y prestaciones sociales | E32: =VLOOKUP(B32,'FLUJO DE CAJA PROYECTADO '!$B$13:$J$61,3,FALSE) -> 1 | F32: =VLOOKUP(B32,'FLUJO DE CAJA PROYECTADO '!$B$13:$J$61,9,FALSE) -> 349306.07 | G32: =VLOOKUP(B32,'FLUJO DE CAJA PROYECTADO '!$B$13:$J$61,8,FALSE) -> 349306.07 | H32: =D32-G32 -> -349306.07 | J32: =VLOOKUP($B32,ASEGURADO!$B$3:$J$51,3,FALSE) -> 1 | K32: =VLOOKUP(B32,ASEGURADO!$B$3:$J$52,9,FALSE) -> 349306.07 | L32: =VLOOKUP($B32,ASEGURADO!$B$3:$J$52,8,FALSE) -> 349306.07 | M32: =G32-L32 -> 0 | P32: =VLOOKUP(B32,REAL!$B$13:$J$61,3,FALSE) -> 1 | Q32: =VLOOKUP(B32,REAL!$B$13:$J$61,9,FALSE) -> 349306.07 | R32: =VLOOKUP(B32,REAL!$B$13:$J$61,8,FALSE) -> 349306.07 | S32: =G32-R32 -> 0 | U32: =VLOOKUP(B32,Contabilidad!$B$3:$D$51,3,FALSE) -> 0 | V32: =R32-U32 -> 349306.07 | X32: =VLOOKUP($B32,'FLUJO DE CAJA PROYECTADO '!$B$13:$AI$66,'Control Flujo de caja'!X$16,FALSE) -> 349306.07 | Y32: =VLOOKUP($B32,REAL!$B$13:$AI$61,'Control Flujo de caja'!Y$16,FALSE) -> 349306.07 | Z32: =X32-Y32 -> 0 | AA32: =VLOOKUP($B32,'FLUJO DE CAJA PROYECTADO '!$B$13:$AI$66,'Control Flujo de caja'!AA$16,FALSE) -> 0 | AB32: =VLOOKUP($B32,REAL!$B$13:$AI$61,'Control Flujo de caja'!AB$16,FALSE) -> 0 | AC32: =AA32-AB32 -> 0 | AD32: =VLOOKUP($B32,'FLUJO DE CAJA PROYECTADO '!$B$13:$AI$66,'Control Flujo de caja'!AD$16,FALSE) -> 0 | AE32: =VLOOKUP($B32,REAL!$B$13:$AI$61,'Control Flujo de caja'!AE$16,FALSE) -> 0 | AF32: =AD32-AE32 -> 0 | AG32: =VLOOKUP($B32,'FLUJO DE CAJA PROYECTADO '!$B$13:$AI$66,'Control Flujo de caja'!AG$16,FALSE) -> 0 | AH32: =VLOOKUP($B32,REAL!$B$13:$AI$61,'Control Flujo de caja'!AH$16,FALSE) -> 0 | AI32: =AG32-AH32 -> 0 | AJ32: =VLOOKUP($B32,'FLUJO DE CAJA PROYECTADO '!$B$13:$AI$66,'Control Flujo de caja'!AJ$16,FALSE) -> 0 | AK32: =VLOOKUP($B32,REAL!$B$13:$AI$61,'Control Flujo de caja'!AK$16,FALSE) -> 0 | AL32: =AJ32-AK32 -> 0 | AM32: =VLOOKUP($B32,'FLUJO DE CAJA PROYECTADO '!$B$13:$AN$66,'Control Flujo de caja'!AM$16,FALSE) -> 0 | AN32: =VLOOKUP($B32,REAL!$B$13:$AN$61,'Control Flujo de caja'!AN$16,FALSE) -> 0 | AO32: =AM32-AN32 -> 0 | AP32: =VLOOKUP($B32,'FLUJO DE CAJA PROYECTADO '!$B$13:$AS$66,'Control Flujo de caja'!AP$16,FALSE) -> 262737 | AQ32: =VLOOKUP($B32,REAL!$B$13:$AS$61,'Control Flujo de caja'!AQ$16,FALSE) -> 0 | AR32: =AP32-AQ32 -> 262737
B33: 1.1.4 | C33: Estabilidad de obra | E33: =VLOOKUP(B33,'FLUJO DE CAJA PROYECTADO '!$B$13:$J$61,3,FALSE) -> 1 | F33: =VLOOKUP(B33,'FLUJO DE CAJA PROYECTADO '!$B$13:$J$61,9,FALSE) -> 4184037.9 | G33: =VLOOKUP(B33,'FLUJO DE CAJA PROYECTADO '!$B$13:$J$61,8,FALSE) -> 4184037.9 | H33: =D33-G33 -> -4184037.9 | J33: =VLOOKUP($B33,ASEGURADO!$B$3:$J$51,3,FALSE) -> 1 | K33: =VLOOKUP(B33,ASEGURADO!$B$3:$J$52,9,FALSE) -> 4184037.9 | L33: =VLOOKUP($B33,ASEGURADO!$B$3:$J$52,8,FALSE) -> 4184037.9 | M33: =G33-L33 -> 0 | P33: =VLOOKUP(B33,REAL!$B$13:$J$61,3,FALSE) -> 1 | Q33: =VLOOKUP(B33,REAL!$B$13:$J$61,9,FALSE) -> 4184037.9 | R33: =VLOOKUP(B33,REAL!$B$13:$J$61,8,FALSE) -> 4184037.9 | S33: =G33-R33 -> 0 | U33: =VLOOKUP(B33,Contabilidad!$B$3:$D$51,3,FALSE) -> 0 | V33: =R33-U33 -> 4184037.9 | X33: =VLOOKUP($B33,'FLUJO DE CAJA PROYECTADO '!$B$13:$AI$66,'Control Flujo de caja'!X$16,FALSE) -> 4184037.9 | Y33: =VLOOKUP($B33,REAL!$B$13:$AI$61,'Control Flujo de caja'!Y$16,FALSE) -> 4184037.9 | Z33: =X33-Y33 -> 0 | AA33: =VLOOKUP($B33,'FLUJO DE CAJA PROYECTADO '!$B$13:$AI$66,'Control Flujo de caja'!AA$16,FALSE) -> 0 | AB33: =VLOOKUP($B33,REAL!$B$13:$AI$61,'Control Flujo de caja'!AB$16,FALSE) -> 0 | AC33: =AA33-AB33 -> 0 | AD33: =VLOOKUP($B33,'FLUJO DE CAJA PROYECTADO '!$B$13:$AI$66,'Control Flujo de caja'!AD$16,FALSE) -> 0 | AE33: =VLOOKUP($B33,REAL!$B$13:$AI$61,'Control Flujo de caja'!AE$16,FALSE) -> 0 | AF33: =AD33-AE33 -> 0 | AG33: =VLOOKUP($B33,'FLUJO DE CAJA PROYECTADO '!$B$13:$AI$66,'Control Flujo de caja'!AG$16,FALSE) -> 0 | AH33: =VLOOKUP($B33,REAL!$B$13:$AI$61,'Control Flujo de caja'!AH$16,FALSE) -> 0 | AI33: =AG33-AH33 -> 0 | AJ33: =VLOOKUP($B33,'FLUJO DE CAJA PROYECTADO '!$B$13:$AI$66,'Control Flujo de caja'!AJ$16,FALSE) -> 0 | AK33: =VLOOKUP($B33,REAL!$B$13:$AI$61,'Control Flujo de caja'!AK$16,FALSE) -> 0 | AL33: =AJ33-AK33 -> 0 | AM33: =VLOOKUP($B33,'FLUJO DE CAJA PROYECTADO '!$B$13:$AN$66,'Control Flujo de caja'!AM$16,FALSE) -> 0 | AN33: =VLOOKUP($B33,REAL!$B$13:$AN$61,'Control Flujo de caja'!AN$16,FALSE) -> 0 | AO33: =AM33-AN33 -> 0 | AP33: =VLOOKUP($B33,'FLUJO DE CAJA PROYECTADO '!$B$13:$AS$66,'Control Flujo de caja'!AP$16,FALSE) -> 3695647 | AQ33: =VLOOKUP($B33,REAL!$B$13:$AS$61,'Control Flujo de caja'!AQ$16,FALSE) -> 0 | AR33: =AP33-AQ33 -> 3695647
B34: 1.1.5 | C34: Calidad de obra | E34: =VLOOKUP(B34,'FLUJO DE CAJA PROYECTADO '!$B$13:$J$61,3,FALSE) -> 1 | F34: =VLOOKUP(B34,'FLUJO DE CAJA PROYECTADO '!$B$13:$J$61,9,FALSE) -> 9282 | G34: =VLOOKUP(B34,'FLUJO DE CAJA PROYECTADO '!$B$13:$J$61,8,FALSE) -> 9282 | H34: =D34-G34 -> -9282 | J34: =VLOOKUP($B34,ASEGURADO!$B$3:$J$51,3,FALSE) -> 1 | K34: =VLOOKUP(B34,ASEGURADO!$B$3:$J$52,9,FALSE) -> 9282 | L34: =VLOOKUP($B34,ASEGURADO!$B$3:$J$52,8,FALSE) -> 9282 | M34: =G34-L34 -> 0 | P34: =VLOOKUP(B34,REAL!$B$13:$J$61,3,FALSE) -> 1 | Q34: =VLOOKUP(B34,REAL!$B$13:$J$61,9,FALSE) -> 9282 | R34: =VLOOKUP(B34,REAL!$B$13:$J$61,8,FALSE) -> 9282 | S34: =G34-R34 -> 0 | U34: =VLOOKUP(B34,Contabilidad!$B$3:$D$51,3,FALSE) -> 0 | V34: =R34-U34 -> 9282 | X34: =VLOOKUP($B34,'FLUJO DE CAJA PROYECTADO '!$B$13:$AI$66,'Control Flujo de caja'!X$16,FALSE) -> 9282 | Y34: =VLOOKUP($B34,REAL!$B$13:$AI$61,'Control Flujo de caja'!Y$16,FALSE) -> 9282 | Z34: =X34-Y34 -> 0 | AA34: =VLOOKUP($B34,'FLUJO DE CAJA PROYECTADO '!$B$13:$AI$66,'Control Flujo de caja'!AA$16,FALSE) -> 0 | AB34: =VLOOKUP($B34,REAL!$B$13:$AI$61,'Control Flujo de caja'!AB$16,FALSE) -> 0 | AC34: =AA34-AB34 -> 0 | AD34: =VLOOKUP($B34,'FLUJO DE CAJA PROYECTADO '!$B$13:$AI$66,'Control Flujo de caja'!AD$16,FALSE) -> 0 | AE34: =VLOOKUP($B34,REAL!$B$13:$AI$61,'Control Flujo de caja'!AE$16,FALSE) -> 0 | AF34: =AD34-AE34 -> 0 | AG34: =VLOOKUP($B34,'FLUJO DE CAJA PROYECTADO '!$B$13:$AI$66,'Control Flujo de caja'!AG$16,FALSE) -> 0 | AH34: =VLOOKUP($B34,REAL!$B$13:$AI$61,'Control Flujo de caja'!AH$16,FALSE) -> 0 | AI34: =AG34-AH34 -> 0 | AJ34: =VLOOKUP($B34,'FLUJO DE CAJA PROYECTADO '!$B$13:$AI$66,'Control Flujo de caja'!AJ$16,FALSE) -> 0 | AK34: =VLOOKUP($B34,REAL!$B$13:$AI$61,'Control Flujo de caja'!AK$16,FALSE) -> 0 | AL34: =AJ34-AK34 -> 0 | AM34: =VLOOKUP($B34,'FLUJO DE CAJA PROYECTADO '!$B$13:$AN$66,'Control Flujo de caja'!AM$16,FALSE) -> 0 | AN34: =VLOOKUP($B34,REAL!$B$13:$AN$61,'Control Flujo de caja'!AN$16,FALSE) -> 0 | AO34: =AM34-AN34 -> 0 | AP34: =VLOOKUP($B34,'FLUJO DE CAJA PROYECTADO '!$B$13:$AS$66,'Control Flujo de caja'!AP$16,FALSE) -> 1212969 | AQ34: =VLOOKUP($B34,REAL!$B$13:$AS$61,'Control Flujo de caja'!AQ$16,FALSE) -> 0 | AR34: =AP34-AQ34 -> 1212969
B35: 1.1.6 | C35: Responsabilidad civil extracontractural | E35: =VLOOKUP(B35,'FLUJO DE CAJA PROYECTADO '!$B$13:$J$61,3,FALSE) -> 1 | F35: =VLOOKUP(B35,'FLUJO DE CAJA PROYECTADO '!$B$13:$J$61,9,FALSE) -> 392285.52 | G35: =VLOOKUP(B35,'FLUJO DE CAJA PROYECTADO '!$B$13:$J$61,8,FALSE) -> 392285.52 | H35: =D35-G35 -> -392285.52 | J35: =VLOOKUP($B35,ASEGURADO!$B$3:$J$51,3,FALSE) -> 1 | K35: =VLOOKUP(B35,ASEGURADO!$B$3:$J$52,9,FALSE) -> 392285.52 | L35: =VLOOKUP($B35,ASEGURADO!$B$3:$J$52,8,FALSE) -> 392285.52 | M35: =G35-L35 -> 0 | P35: =VLOOKUP(B35,REAL!$B$13:$J$61,3,FALSE) -> 1 | Q35: =VLOOKUP(B35,REAL!$B$13:$J$61,9,FALSE) -> 392285.52 | R35: =VLOOKUP(B35,REAL!$B$13:$J$61,8,FALSE) -> 392285.52 | S35: =G35-R35 -> 0 | U35: =VLOOKUP(B35,Contabilidad!$B$3:$D$51,3,FALSE) -> 0 | V35: =R35-U35 -> 392285.52 | X35: =VLOOKUP($B35,'FLUJO DE CAJA PROYECTADO '!$B$13:$AI$66,'Control Flujo de caja'!X$16,FALSE) -> 392285.52 | Y35: =VLOOKUP($B35,REAL!$B$13:$AI$61,'Control Flujo de caja'!Y$16,FALSE) -> 392285.52 | Z35: =X35-Y35 -> 0 | AA35: =VLOOKUP($B35,'FLUJO DE CAJA PROYECTADO '!$B$13:$AI$66,'Control Flujo de caja'!AA$16,FALSE) -> 0 | AB35: =VLOOKUP($B35,REAL!$B$13:$AI$61,'Control Flujo de caja'!AB$16,FALSE) -> 0 | AC35: =AA35-AB35 -> 0 | AD35: =VLOOKUP($B35,'FLUJO DE CAJA PROYECTADO '!$B$13:$AI$66,'Control Flujo de caja'!AD$16,FALSE) -> 0 | AE35: =VLOOKUP($B35,REAL!$B$13:$AI$61,'Control Flujo de caja'!AE$16,FALSE) -> 0 | AF35: =AD35-AE35 -> 0 | AG35: =VLOOKUP($B35,'FLUJO DE CAJA PROYECTADO '!$B$13:$AI$66,'Control Flujo de caja'!AG$16,FALSE) -> 0 | AH35: =VLOOKUP($B35,REAL!$B$13:$AI$61,'Control Flujo de caja'!AH$16,FALSE) -> 0 | AI35: =AG35-AH35 -> 0 | AJ35: =VLOOKUP($B35,'FLUJO DE CAJA PROYECTADO '!$B$13:$AI$66,'Control Flujo de caja'!AJ$16,FALSE) -> 0 | AK35: =VLOOKUP($B35,REAL!$B$13:$AI$61,'Control Flujo de caja'!AK$16,FALSE) -> 0 | AL35: =AJ35-AK35 -> 0 | AM35: =VLOOKUP($B35,'FLUJO DE CAJA PROYECTADO '!$B$13:$AN$66,'Control Flujo de caja'!AM$16,FALSE) -> 0 | AN35: =VLOOKUP($B35,REAL!$B$13:$AN$61,'Control Flujo de caja'!AN$16,FALSE) -> 0 | AO35: =AM35-AN35 -> 0 | AP35: =VLOOKUP($B35,'FLUJO DE CAJA PROYECTADO '!$B$13:$AS$66,'Control Flujo de caja'!AP$16,FALSE) -> 590277 | AQ35: =VLOOKUP($B35,REAL!$B$13:$AS$61,'Control Flujo de caja'!AQ$16,FALSE) -> 0 | AR35: =AP35-AQ35 -> 590277
B36: 1.2. | C36: Impuestos | D36: 48300865 | E36: =SUM(E37:E39) -> 3 | F36: =SUM(F37:F39) -> 48300863 | G36: =SUM(G37:G39) -> 0 | H36: =D36-G36 -> 48300865 | J36: =SUM(J37:J39) -> 3 | K36: =SUM(K37:K39) -> 48300863 | L36: =SUM(L37:L39) -> 0 | M36: =SUM(M37:M39) -> 0 | P36: =SUM(P37:P39) -> 3 | Q36: =SUM(Q37:Q39) -> 48300863 | R36: =SUM(R37:R39) -> 0 | S36: =G36-R36 -> 0 | U36: =VLOOKUP(B36,Contabilidad!$B$3:$D$51,3,FALSE) -> 0 | V36: =SUM(V37:V39) -> 0 | X36: =SUM(X37:X39) -> 0 | Y36: =SUM(Y37:Y39) -> 0 | Z36: =SUM(Z37:Z39) -> 0 | AA36: =SUM(AA37:AA39) -> 0 | AB36: =SUM(AB37:AB39) -> 0 | AC36: =SUM(AC37:AC39) -> 0 | AD36: =SUM(AD37:AD39) -> 0 | AE36: =SUM(AE37:AE39) -> 0 | ... AR36: =SUM(AR37:AR39) -> 48300865
B37: 1.2.1 | C37: FIC | E37: =VLOOKUP(B37,'FLUJO DE CAJA PROYECTADO '!$B$13:$J$61,3,FALSE) -> 1 | F37: =VLOOKUP(B37,'FLUJO DE CAJA PROYECTADO '!$B$13:$J$61,9,FALSE) -> 7318312 | G37: =VLOOKUP(B37,'FLUJO DE CAJA PROYECTADO '!$B$13:$J$61,8,FALSE) -> 0 | H37: =D37-G37 -> 0 | J37: =VLOOKUP($B37,ASEGURADO!$B$3:$J$51,3,FALSE) -> 1 | K37: =VLOOKUP(B37,ASEGURADO!$B$3:$J$52,9,FALSE) -> 7318312 | L37: =VLOOKUP($B37,ASEGURADO!$B$3:$J$52,8,FALSE) -> 0 | M37: =G37-L37 -> 0 | P37: =VLOOKUP(B37,REAL!$B$13:$J$61,3,FALSE) -> 1 | Q37: =VLOOKUP(B37,REAL!$B$13:$J$61,9,FALSE) -> 7318312 | R37: =VLOOKUP(B37,REAL!$B$13:$J$61,8,FALSE) -> 0 | S37: =G37-R37 -> 0 | U37: =VLOOKUP(B37,Contabilidad!$B$3:$D$51,3,FALSE) -> 0 | V37: =R37-U37 -> 0 | X37: =VLOOKUP($B37,'FLUJO DE CAJA PROYECTADO '!$B$13:$AI$66,'Control Flujo de caja'!X$16,FALSE) -> 0 | Y37: =VLOOKUP($B37,REAL!$B$13:$AI$61,'Control Flujo de caja'!Y$16,FALSE) -> 0 | Z37: =X37-Y37 -> 0 | AA37: =VLOOKUP($B37,'FLUJO DE CAJA PROYECTADO '!$B$13:$AI$66,'Control Flujo de caja'!AA$16,FALSE) -> 0 | AB37: =VLOOKUP($B37,REAL!$B$13:$AI$61,'Control Flujo de caja'!AB$16,FALSE) -> 0 | AC37: =AA37-AB37 -> 0 | AD37: =VLOOKUP($B37,'FLUJO DE CAJA PROYECTADO '!$B$13:$AI$66,'Control Flujo de caja'!AD$16,FALSE) -> 0 | AE37: =VLOOKUP($B37,REAL!$B$13:$AI$61,'Control Flujo de caja'!AE$16,FALSE) -> 0 | AF37: =AD37-AE37 -> 0 | AG37: =VLOOKUP($B37,'FLUJO DE CAJA PROYECTADO '!$B$13:$AI$66,'Control Flujo de caja'!AG$16,FALSE) -> 0 | AH37: =VLOOKUP($B37,REAL!$B$13:$AI$61,'Control Flujo de caja'!AH$16,FALSE) -> 0 | AI37: =AG37-AH37 -> 0 | AJ37: =VLOOKUP($B37,'FLUJO DE CAJA PROYECTADO '!$B$13:$AI$66,'Control Flujo de caja'!AJ$16,FALSE) -> 0 | AK37: =VLOOKUP($B37,REAL!$B$13:$AI$61,'Control Flujo de caja'!AK$16,FALSE) -> 0 | AL37: =AJ37-AK37 -> 0 | AM37: =VLOOKUP($B37,'FLUJO DE CAJA PROYECTADO '!$B$13:$AN$66,'Control Flujo de caja'!AM$16,FALSE) -> 0 | AN37: =VLOOKUP($B37,REAL!$B$13:$AN$61,'Control Flujo de caja'!AN$16,FALSE) -> 0 | AO37: =AM37-AN37 -> 0 | AP37: =VLOOKUP($B37,'FLUJO DE CAJA PROYECTADO '!$B$13:$AS$66,'Control Flujo de caja'!AP$16,FALSE) -> 7318312.9 | AQ37: =VLOOKUP($B37,REAL!$B$13:$AS$61,'Control Flujo de caja'!AQ$16,FALSE) -> 0 | AR37: =AP37-AQ37 -> 7318312.9
B38: 1.2.2 | C38: ICA | E38: =VLOOKUP(B38,'FLUJO DE CAJA PROYECTADO '!$B$13:$J$61,3,FALSE) -> 1 | F38: =VLOOKUP(B38,'FLUJO DE CAJA PROYECTADO '!$B$13:$J$61,9,FALSE) -> 29273251 | G38: =VLOOKUP(B38,'FLUJO DE CAJA PROYECTADO '!$B$13:$J$61,8,FALSE) -> 0 | H38: =D38-G38 -> 0 | J38: =VLOOKUP($B38,ASEGURADO!$B$3:$J$51,3,FALSE) -> 1 | K38: =VLOOKUP(B38,ASEGURADO!$B$3:$J$52,9,FALSE) -> 29273251 | L38: =VLOOKUP($B38,ASEGURADO!$B$3:$J$52,8,FALSE) -> 0 | M38: =G38-L38 -> 0 | P38: =VLOOKUP(B38,REAL!$B$13:$J$61,3,FALSE) -> 1 | Q38: =VLOOKUP(B38,REAL!$B$13:$J$61,9,FALSE) -> 29273251 | R38: =VLOOKUP(B38,REAL!$B$13:$J$61,8,FALSE) -> 0 | S38: =G38-R38 -> 0 | U38: =VLOOKUP(B38,Contabilidad!$B$3:$D$51,3,FALSE) -> 0 | V38: =R38-U38 -> 0 | X38: =VLOOKUP($B38,'FLUJO DE CAJA PROYECTADO '!$B$13:$AI$66,'Control Flujo de caja'!X$16,FALSE) -> 0 | Y38: =VLOOKUP($B38,REAL!$B$13:$AI$61,'Control Flujo de caja'!Y$16,FALSE) -> 0 | Z38: =X38-Y38 -> 0 | AA38: =VLOOKUP($B38,'FLUJO DE CAJA PROYECTADO '!$B$13:$AI$66,'Control Flujo de caja'!AA$16,FALSE) -> 0 | AB38: =VLOOKUP($B38,REAL!$B$13:$AI$61,'Control Flujo de caja'!AB$16,FALSE) -> 0 | AC38: =AA38-AB38 -> 0 | AD38: =VLOOKUP($B38,'FLUJO DE CAJA PROYECTADO '!$B$13:$AI$66,'Control Flujo de caja'!AD$16,FALSE) -> 0 | AE38: =VLOOKUP($B38,REAL!$B$13:$AI$61,'Control Flujo de caja'!AE$16,FALSE) -> 0 | AF38: =AD38-AE38 -> 0 | AG38: =VLOOKUP($B38,'FLUJO DE CAJA PROYECTADO '!$B$13:$AI$66,'Control Flujo de caja'!AG$16,FALSE) -> 0 | AH38: =VLOOKUP($B38,REAL!$B$13:$AI$61,'Control Flujo de caja'!AH$16,FALSE) -> 0 | AI38: =AG38-AH38 -> 0 | AJ38: =VLOOKUP($B38,'FLUJO DE CAJA PROYECTADO '!$B$13:$AI$66,'Control Flujo de caja'!AJ$16,FALSE) -> 0 | AK38: =VLOOKUP($B38,REAL!$B$13:$AI$61,'Control Flujo de caja'!AK$16,FALSE) -> 0 | AL38: =AJ38-AK38 -> 0 | AM38: =VLOOKUP($B38,'FLUJO DE CAJA PROYECTADO '!$B$13:$AN$66,'Control Flujo de caja'!AM$16,FALSE) -> 0 | AN38: =VLOOKUP($B38,REAL!$B$13:$AN$61,'Control Flujo de caja'!AN$16,FALSE) -> 0 | AO38: =AM38-AN38 -> 0 | AP38: =VLOOKUP($B38,'FLUJO DE CAJA PROYECTADO '!$B$13:$AS$66,'Control Flujo de caja'!AP$16,FALSE) -> 29273252 | AQ38: =VLOOKUP($B38,REAL!$B$13:$AS$61,'Control Flujo de caja'!AQ$16,FALSE) -> 0 | AR38: =AP38-AQ38 -> 29273252
B39: 1.2.3 | C39: Cuatro por 1000 | E39: =VLOOKUP(B39,'FLUJO DE CAJA PROYECTADO '!$B$13:$J$61,3,FALSE) -> 1 | F39: =VLOOKUP(B39,'FLUJO DE CAJA PROYECTADO '!$B$13:$J$61,9,FALSE) -> 11709300 | G39: =VLOOKUP(B39,'FLUJO DE CAJA PROYECTADO '!$B$13:$J$61,8,FALSE) -> 0 | H39: =D39-G39 -> 0 | J39: =VLOOKUP($B39,ASEGURADO!$B$3:$J$51,3,FALSE) -> 1 | K39: =VLOOKUP(B39,ASEGURADO!$B$3:$J$52,9,FALSE) -> 11709300 | L39: =VLOOKUP($B39,ASEGURADO!$B$3:$J$52,8,FALSE) -> 0 | M39: =G39-L39 -> 0 | P39: =VLOOKUP(B39,REAL!$B$13:$J$61,3,FALSE) -> 1 | Q39: =VLOOKUP(B39,REAL!$B$13:$J$61,9,FALSE) -> 11709300 | R39: =VLOOKUP(B39,REAL!$B$13:$J$61,8,FALSE) -> 0 | S39: =G39-R39 -> 0 | U39: =VLOOKUP(B39,Contabilidad!$B$3:$D$51,3,FALSE) -> 0 | V39: =R39-U39 -> 0 | X39: =VLOOKUP($B39,'FLUJO DE CAJA PROYECTADO '!$B$13:$AI$66,'Control Flujo de caja'!X$16,FALSE) -> 0 | Y39: =VLOOKUP($B39,REAL!$B$13:$AI$61,'Control Flujo de caja'!Y$16,FALSE) -> 0 | Z39: =X39-Y39 -> 0 | AA39: =VLOOKUP($B39,'FLUJO DE CAJA PROYECTADO '!$B$13:$AI$66,'Control Flujo de caja'!AA$16,FALSE) -> 0 | AB39: =VLOOKUP($B39,REAL!$B$13:$AI$61,'Control Flujo de caja'!AB$16,FALSE) -> 0 | AC39: =AA39-AB39 -> 0 | AD39: =VLOOKUP($B39,'FLUJO DE CAJA PROYECTADO '!$B$13:$AI$66,'Control Flujo de caja'!AD$16,FALSE) -> 0 | AE39: =VLOOKUP($B39,REAL!$B$13:$AI$61,'Control Flujo de caja'!AE$16,FALSE) -> 0 | AF39: =AD39-AE39 -> 0 | AG39: =VLOOKUP($B39,'FLUJO DE CAJA PROYECTADO '!$B$13:$AI$66,'Control Flujo de caja'!AG$16,FALSE) -> 0 | AH39: =VLOOKUP($B39,REAL!$B$13:$AI$61,'Control Flujo de caja'!AH$16,FALSE) -> 0 | AI39: =AG39-AH39 -> 0 | AJ39: =VLOOKUP($B39,'FLUJO DE CAJA PROYECTADO '!$B$13:$AI$66,'Control Flujo de caja'!AJ$16,FALSE) -> 0 | AK39: =VLOOKUP($B39,REAL!$B$13:$AI$61,'Control Flujo de caja'!AK$16,FALSE) -> 0 | AL39: =AJ39-AK39 -> 0 | AM39: =VLOOKUP($B39,'FLUJO DE CAJA PROYECTADO '!$B$13:$AN$66,'Control Flujo de caja'!AM$16,FALSE) -> 0 | AN39: =VLOOKUP($B39,REAL!$B$13:$AN$61,'Control Flujo de caja'!AN$16,FALSE) -> 0 | AO39: =AM39-AN39 -> 0 | AP39: =VLOOKUP($B39,'FLUJO DE CAJA PROYECTADO '!$B$13:$AS$66,'Control Flujo de caja'!AP$16,FALSE) -> 11709301 | AQ39: =VLOOKUP($B39,REAL!$B$13:$AS$61,'Control Flujo de caja'!AQ$16,FALSE) -> 0 | AR39: =AP39-AQ39 -> 11709301
B40: 1.3 | C40: Personal administración | D40: 24640000 | E40: =E41 -> 4 | F40: =F41 -> 7000000 | G40: =SUM(G41:G42) -> 34339945 | H40: =D40-G40 -> -9699945 | J40: =J41 -> 4 | K40: =K41 -> 7000000 | L40: =L41 -> 2435886 | M40: =M41 -> 14654059 | P40: =SUM(P41:P42) -> 8 | Q40: =SUM(Q41:Q42) -> 10450000 | R40: =SUM(R41:R42) -> 23736902 | S40: =G40-R40 -> 10603043 | U40: =SUM(U41:U42) -> 8202317 | V40: =V41 -> 4441021 | X40: =SUM(X41:X42) -> 2435886 | Y40: =SUM(Y41:Y42) -> 2435886 | Z40: =SUM(Z41:Z42) -> 0 | AA40: =SUM(AA41:AA42) -> 10365382 | AB40: =SUM(AB41:AB42) -> 10362570 | AC40: =SUM(AC41:AC42) -> 2812 | AD40: =SUM(AD41:AD42) -> 10365382 | AE40: =SUM(AE41:AE42) -> 7315258 | ... AR40: =SUM(AR41:AR42) -> 4273295
B41: 1.3.1 | C41: Profesional de calidad 100% | E41: =VLOOKUP(B41,'FLUJO DE CAJA PROYECTADO '!$B$13:$J$61,3,FALSE) -> 4 | F41: =VLOOKUP(B41,'FLUJO DE CAJA PROYECTADO '!$B$13:$J$61,9,FALSE) -> 7000000 | G41: =VLOOKUP(B41,'FLUJO DE CAJA PROYECTADO '!$B$13:$J$61,8,FALSE) -> 17089945 | H41: =D41-G41 -> -17089945 | J41: =VLOOKUP($B41,ASEGURADO!$B$3:$J$51,3,FALSE) -> 4 | K41: =VLOOKUP(B41,ASEGURADO!$B$3:$J$52,9,FALSE) -> 7000000 | L41: =VLOOKUP($B41,ASEGURADO!$B$3:$J$52,8,FALSE) -> 2435886 | M41: =G41-L41 -> 14654059 | P41: =VLOOKUP(B41,REAL!$B$13:$J$61,3,FALSE) -> 4 | Q41: =VLOOKUP(B41,REAL!$B$13:$J$61,9,FALSE) -> 7000000 | R41: =VLOOKUP(B41,REAL!$B$13:$J$61,8,FALSE) -> 12643338 | S41: =G41-R41 -> 4446607 | U41: =VLOOKUP(B41,Contabilidad!$B$3:$D$51,3,FALSE) -> 8202317 | V41: =R41-U41 -> 4441021 | X41: =VLOOKUP($B41,'FLUJO DE CAJA PROYECTADO '!$B$13:$AI$66,'Control Flujo de caja'!X$16,FALSE) -> 2435886 | Y41: =VLOOKUP($B41,REAL!$B$13:$AI$61,'Control Flujo de caja'!Y$16,FALSE) -> 2435886 | Z41: =X41-Y41 -> 0 | AA41: =VLOOKUP($B41,'FLUJO DE CAJA PROYECTADO '!$B$13:$AI$66,'Control Flujo de caja'!AA$16,FALSE) -> 6915382 | AB41: =VLOOKUP($B41,REAL!$B$13:$AI$61,'Control Flujo de caja'!AB$16,FALSE) -> 6515382 | AC41: =AA41-AB41 -> 400000 | AD41: =VLOOKUP($B41,'FLUJO DE CAJA PROYECTADO '!$B$13:$AI$66,'Control Flujo de caja'!AD$16,FALSE) -> 6915382 | AE41: =VLOOKUP($B41,REAL!$B$13:$AI$61,'Control Flujo de caja'!AE$16,FALSE) -> 3692070 | AF41: =AD41-AE41 -> 3223312 | AG41: =VLOOKUP($B41,'FLUJO DE CAJA PROYECTADO '!$B$13:$AI$66,'Control Flujo de caja'!AG$16,FALSE) -> 0 | AH41: =VLOOKUP($B41,REAL!$B$13:$AI$61,'Control Flujo de caja'!AH$16,FALSE) -> 0 | AI41: =AG41-AH41 -> 0 | AJ41: =VLOOKUP($B41,'FLUJO DE CAJA PROYECTADO '!$B$13:$AI$66,'Control Flujo de caja'!AJ$16,FALSE) -> 0 | AK41: =VLOOKUP($B41,REAL!$B$13:$AI$61,'Control Flujo de caja'!AK$16,FALSE) -> 0 | AL41: =AJ41-AK41 -> 0 | AM41: =VLOOKUP($B41,'FLUJO DE CAJA PROYECTADO '!$B$13:$AN$66,'Control Flujo de caja'!AM$16,FALSE) -> 823295 | AN41: =VLOOKUP($B41,REAL!$B$13:$AN$61,'Control Flujo de caja'!AN$16,FALSE) -> 0 | AO41: =AM41-AN41 -> 823295 | AP41: =VLOOKUP($B41,'FLUJO DE CAJA PROYECTADO '!$B$13:$AS$66,'Control Flujo de caja'!AP$16,FALSE) -> 823295 | AQ41: =VLOOKUP($B41,REAL!$B$13:$AS$61,'Control Flujo de caja'!AQ$16,FALSE) -> 0 | AR41: =AP41-AQ41 -> 823295
